Process A [NEW] (arrival time 176 ms) 75 CPU bursts
Process B [NEW] (arrival time 42 ms) 85 CPU bursts
Process C [NEW] (arrival time 17 ms) 58 CPU bursts
Process D [NEW] (arrival time 76 ms) 68 CPU bursts
Process E [NEW] (arrival time 1 ms) 2 CPU bursts
Process F [NEW] (arrival time 56 ms) 14 CPU bursts
Process G [NEW] (arrival time 20 ms) 79 CPU bursts
Process H [NEW] (arrival time 207 ms) 54 CPU bursts
Process I [NEW] (arrival time 94 ms) 59 CPU bursts
Process J [NEW] (arrival time 13 ms) 3 CPU bursts
Process K [NEW] (arrival time 42 ms) 88 CPU bursts
Process L [NEW] (arrival time 76 ms) 25 CPU bursts
Process M [NEW] (arrival time 33 ms) 38 CPU bursts
Process N [NEW] (arrival time 65 ms) 58 CPU bursts
Process O [NEW] (arrival time 122 ms) 56 CPU bursts
Process P [NEW] (arrival time 40 ms) 85 CPU bursts
Process Q [NEW] (arrival time 187 ms) 91 CPU bursts
Process R [NEW] (arrival time 1 ms) 50 CPU bursts
Process S [NEW] (arrival time 286 ms) 32 CPU bursts
Process T [NEW] (arrival time 33 ms) 52 CPU bursts
Process U [NEW] (arrival time 13 ms) 53 CPU bursts
Process V [NEW] (arrival time 12 ms) 32 CPU bursts
Process W [NEW] (arrival time 112 ms) 23 CPU bursts
Process X [NEW] (arrival time 28 ms) 1 CPU burst
Process Y [NEW] (arrival time 169 ms) 30 CPU bursts
Process Z [NEW] (arrival time 28 ms) 85 CPU bursts
time 0ms: Simulator started for FCFS [Q <empty>]
time 1ms: Process E arrived; added to ready queue [Q E]
time 1ms: Process R arrived; added to ready queue [Q E R]
time 4ms: Process E started using the CPU for 15ms burst [Q R]
time 12ms: Process V arrived; added to ready queue [Q R V]
time 13ms: Process J arrived; added to ready queue [Q R V J]
time 13ms: Process U arrived; added to ready queue [Q R V J U]
time 17ms: Process C arrived; added to ready queue [Q R V J U C]
time 19ms: Process E completed a CPU burst; 1 burst to go [Q R V J U C]
time 19ms: Process E switching out of CPU; will block on I/O until time 234ms [Q R V J U C]
time 20ms: Process G arrived; added to ready queue [Q R V J U C G]
time 25ms: Process R started using the CPU for 289ms burst [Q V J U C G]
time 28ms: Process X arrived; added to ready queue [Q V J U C G X]
time 28ms: Process Z arrived; added to ready queue [Q V J U C G X Z]
time 33ms: Process M arrived; added to ready queue [Q V J U C G X Z M]
time 33ms: Process T arrived; added to ready queue [Q V J U C G X Z M T]
time 40ms: Process P arrived; added to ready queue [Q V J U C G X Z M T P]
time 42ms: Process B arrived; added to ready queue [Q V J U C G X Z M T P B]
time 42ms: Process K arrived; added to ready queue [Q V J U C G X Z M T P B K]
time 56ms: Process F arrived; added to ready queue [Q V J U C G X Z M T P B K F]
time 65ms: Process N arrived; added to ready queue [Q V J U C G X Z M T P B K F N]
time 76ms: Process D arrived; added to ready queue [Q V J U C G X Z M T P B K F N D]
time 76ms: Process L arrived; added to ready queue [Q V J U C G X Z M T P B K F N D L]
time 94ms: Process I arrived; added to ready queue [Q V J U C G X Z M T P B K F N D L I]
time 112ms: Process W arrived; added to ready queue [Q V J U C G X Z M T P B K F N D L I W]
time 122ms: Process O arrived; added to ready queue [Q V J U C G X Z M T P B K F N D L I W O]
time 169ms: Process Y arrived; added to ready queue [Q V J U C G X Z M T P B K F N D L I W O Y]
time 176ms: Process A arrived; added to ready queue [Q V J U C G X Z M T P B K F N D L I W O Y A]
time 187ms: Process Q arrived; added to ready queue [Q V J U C G X Z M T P B K F N D L I W O Y A Q]
time 207ms: Process H arrived; added to ready queue [Q V J U C G X Z M T P B K F N D L I W O Y A Q H]
time 234ms: Process E completed I/O; added to ready queue [Q V J U C G X Z M T P B K F N D L I W O Y A Q H E]
time 286ms: Process S arrived; added to ready queue [Q V J U C G X Z M T P B K F N D L I W O Y A Q H E S]
time 314ms: Process R completed a CPU burst; 49 bursts to go [Q V J U C G X Z M T P B K F N D L I W O Y A Q H E S]
time 314ms: Process R switching out of CPU; will block on I/O until time 410ms [Q V J U C G X Z M T P B K F N D L I W O Y A Q H E S]
time 320ms: Process V started using the CPU for 299ms burst [Q J U C G X Z M T P B K F N D L I W O Y A Q H E S]
time 410ms: Process R completed I/O; added to ready queue [Q J U C G X Z M T P B K F N D L I W O Y A Q H E S R]
time 619ms: Process V completed a CPU burst; 31 bursts to go [Q J U C G X Z M T P B K F N D L I W O Y A Q H E S R]
time 619ms: Process V switching out of CPU; will block on I/O until time 883ms [Q J U C G X Z M T P B K F N D L I W O Y A Q H E S R]
time 625ms: Process J started using the CPU for 325ms burst [Q U C G X Z M T P B K F N D L I W O Y A Q H E S R]
time 883ms: Process V completed I/O; added to ready queue [Q U C G X Z M T P B K F N D L I W O Y A Q H E S R V]
time 950ms: Process J completed a CPU burst; 2 bursts to go [Q U C G X Z M T P B K F N D L I W O Y A Q H E S R V]
time 950ms: Process J switching out of CPU; will block on I/O until time 982ms [Q U C G X Z M T P B K F N D L I W O Y A Q H E S R V]
time 956ms: Process U started using the CPU for 246ms burst [Q C G X Z M T P B K F N D L I W O Y A Q H E S R V]
time 982ms: Process J completed I/O; added to ready queue [Q C G X Z M T P B K F N D L I W O Y A Q H E S R V J]
time 1202ms: Process U completed a CPU burst; 52 bursts to go [Q C G X Z M T P B K F N D L I W O Y A Q H E S R V J]
time 1202ms: Process U switching out of CPU; will block on I/O until time 1306ms [Q C G X Z M T P B K F N D L I W O Y A Q H E S R V J]
time 1208ms: Process C started using the CPU for 170ms burst [Q G X Z M T P B K F N D L I W O Y A Q H E S R V J]
time 1306ms: Process U completed I/O; added to ready queue [Q G X Z M T P B K F N D L I W O Y A Q H E S R V J U]
time 1378ms: Process C completed a CPU burst; 57 bursts to go [Q G X Z M T P B K F N D L I W O Y A Q H E S R V J U]
time 1378ms: Process C switching out of CPU; will block on I/O until time 1745ms [Q G X Z M T P B K F N D L I W O Y A Q H E S R V J U]
time 1384ms: Process G started using the CPU for 35ms burst [Q X Z M T P B K F N D L I W O Y A Q H E S R V J U]
time 1419ms: Process G completed a CPU burst; 78 bursts to go [Q X Z M T P B K F N D L I W O Y A Q H E S R V J U]
time 1419ms: Process G switching out of CPU; will block on I/O until time 1530ms [Q X Z M T P B K F N D L I W O Y A Q H E S R V J U]
time 1425ms: Process X started using the CPU for 1ms burst [Q Z M T P B K F N D L I W O Y A Q H E S R V J U]
time 1426ms: Process X terminated [Q Z M T P B K F N D L I W O Y A Q H E S R V J U]
time 1432ms: Process Z started using the CPU for 103ms burst [Q M T P B K F N D L I W O Y A Q H E S R V J U]
time 1530ms: Process G completed I/O; added to ready queue [Q M T P B K F N D L I W O Y A Q H E S R V J U G]
time 1535ms: Process Z completed a CPU burst; 84 bursts to go [Q M T P B K F N D L I W O Y A Q H E S R V J U G]
time 1535ms: Process Z switching out of CPU; will block on I/O until time 1602ms [Q M T P B K F N D L I W O Y A Q H E S R V J U G]
time 1541ms: Process M started using the CPU for 170ms burst [Q T P B K F N D L I W O Y A Q H E S R V J U G]
time 1602ms: Process Z completed I/O; added to ready queue [Q T P B K F N D L I W O Y A Q H E S R V J U G Z]
time 1711ms: Process M completed a CPU burst; 37 bursts to go [Q T P B K F N D L I W O Y A Q H E S R V J U G Z]
time 1711ms: Process M switching out of CPU; will block on I/O until time 1726ms [Q T P B K F N D L I W O Y A Q H E S R V J U G Z]
time 1717ms: Process T started using the CPU for 92ms burst [Q P B K F N D L I W O Y A Q H E S R V J U G Z]
time 1726ms: Process M completed I/O; added to ready queue [Q P B K F N D L I W O Y A Q H E S R V J U G Z M]
time 1745ms: Process C completed I/O; added to ready queue [Q P B K F N D L I W O Y A Q H E S R V J U G Z M C]
time 1809ms: Process T completed a CPU burst; 51 bursts to go [Q P B K F N D L I W O Y A Q H E S R V J U G Z M C]
time 1809ms: Process T switching out of CPU; will block on I/O until time 2033ms [Q P B K F N D L I W O Y A Q H E S R V J U G Z M C]
time 1815ms: Process P started using the CPU for 161ms burst [Q B K F N D L I W O Y A Q H E S R V J U G Z M C]
time 1976ms: Process P completed a CPU burst; 84 bursts to go [Q B K F N D L I W O Y A Q H E S R V J U G Z M C]
time 1976ms: Process P switching out of CPU; will block on I/O until time 1990ms [Q B K F N D L I W O Y A Q H E S R V J U G Z M C]
time 1982ms: Process B started using the CPU for 39ms burst [Q K F N D L I W O Y A Q H E S R V J U G Z M C]
time 1990ms: Process P completed I/O; added to ready queue [Q K F N D L I W O Y A Q H E S R V J U G Z M C P]
time 2021ms: Process B completed a CPU burst; 84 bursts to go [Q K F N D L I W O Y A Q H E S R V J U G Z M C P]
time 2021ms: Process B switching out of CPU; will block on I/O until time 2028ms [Q K F N D L I W O Y A Q H E S R V J U G Z M C P]
time 2027ms: Process K started using the CPU for 153ms burst [Q F N D L I W O Y A Q H E S R V J U G Z M C P]
time 2028ms: Process B completed I/O; added to ready queue [Q F N D L I W O Y A Q H E S R V J U G Z M C P B]
time 2033ms: Process T completed I/O; added to ready queue [Q F N D L I W O Y A Q H E S R V J U G Z M C P B T]
time 2180ms: Process K completed a CPU burst; 87 bursts to go [Q F N D L I W O Y A Q H E S R V J U G Z M C P B T]
time 2180ms: Process K switching out of CPU; will block on I/O until time 2185ms [Q F N D L I W O Y A Q H E S R V J U G Z M C P B T]
time 2185ms: Process K completed I/O; added to ready queue [Q N D L I W O Y A Q H E S R V J U G Z M C P B T K]
time 2186ms: Process F started using the CPU for 15ms burst [Q N D L I W O Y A Q H E S R V J U G Z M C P B T K]
time 2201ms: Process F completed a CPU burst; 13 bursts to go [Q N D L I W O Y A Q H E S R V J U G Z M C P B T K]
time 2201ms: Process F switching out of CPU; will block on I/O until time 2265ms [Q N D L I W O Y A Q H E S R V J U G Z M C P B T K]
time 2207ms: Process N started using the CPU for 12ms burst [Q D L I W O Y A Q H E S R V J U G Z M C P B T K]
time 2219ms: Process N completed a CPU burst; 57 bursts to go [Q D L I W O Y A Q H E S R V J U G Z M C P B T K]
time 2219ms: Process N switching out of CPU; will block on I/O until time 2253ms [Q D L I W O Y A Q H E S R V J U G Z M C P B T K]
time 2225ms: Process D started using the CPU for 12ms burst [Q L I W O Y A Q H E S R V J U G Z M C P B T K]
time 2237ms: Process D completed a CPU burst; 67 bursts to go [Q L I W O Y A Q H E S R V J U G Z M C P B T K]
time 2237ms: Process D switching out of CPU; will block on I/O until time 2256ms [Q L I W O Y A Q H E S R V J U G Z M C P B T K]
time 2243ms: Process L started using the CPU for 18ms burst [Q I W O Y A Q H E S R V J U G Z M C P B T K]
time 2253ms: Process N completed I/O; added to ready queue [Q I W O Y A Q H E S R V J U G Z M C P B T K N]
time 2256ms: Process D completed I/O; added to ready queue [Q I W O Y A Q H E S R V J U G Z M C P B T K N D]
time 2261ms: Process L completed a CPU burst; 24 bursts to go [Q I W O Y A Q H E S R V J U G Z M C P B T K N D]
time 2261ms: Process L switching out of CPU; will block on I/O until time 2379ms [Q I W O Y A Q H E S R V J U G Z M C P B T K N D]
time 2265ms: Process F completed I/O; added to ready queue [Q W O Y A Q H E S R V J U G Z M C P B T K N D F]
time 2267ms: Process I started using the CPU for 1ms burst [Q W O Y A Q H E S R V J U G Z M C P B T K N D F]
time 2268ms: Process I completed a CPU burst; 58 bursts to go [Q W O Y A Q H E S R V J U G Z M C P B T K N D F]
time 2268ms: Process I switching out of CPU; will block on I/O until time 2276ms [Q W O Y A Q H E S R V J U G Z M C P B T K N D F]
time 2274ms: Process W started using the CPU for 106ms burst [Q O Y A Q H E S R V J U G Z M C P B T K N D F]
time 2276ms: Process I completed I/O; added to ready queue [Q O Y A Q H E S R V J U G Z M C P B T K N D F I]
time 2379ms: Process L completed I/O; added to ready queue [Q O Y A Q H E S R V J U G Z M C P B T K N D F I L]
time 2380ms: Process W completed a CPU burst; 22 bursts to go [Q O Y A Q H E S R V J U G Z M C P B T K N D F I L]
time 2380ms: Process W switching out of CPU; will block on I/O until time 2491ms [Q O Y A Q H E S R V J U G Z M C P B T K N D F I L]
time 2386ms: Process O started using the CPU for 4ms burst [Q Y A Q H E S R V J U G Z M C P B T K N D F I L]
time 2390ms: Process O completed a CPU burst; 55 bursts to go [Q Y A Q H E S R V J U G Z M C P B T K N D F I L]
time 2390ms: Process O switching out of CPU; will block on I/O until time 2619ms [Q Y A Q H E S R V J U G Z M C P B T K N D F I L]
time 2396ms: Process Y started using the CPU for 114ms burst [Q A Q H E S R V J U G Z M C P B T K N D F I L]
time 2491ms: Process W completed I/O; added to ready queue [Q A Q H E S R V J U G Z M C P B T K N D F I L W]
time 2510ms: Process Y completed a CPU burst; 29 bursts to go [Q A Q H E S R V J U G Z M C P B T K N D F I L W]
time 2510ms: Process Y switching out of CPU; will block on I/O until time 2743ms [Q A Q H E S R V J U G Z M C P B T K N D F I L W]
time 2516ms: Process A started using the CPU for 234ms burst [Q Q H E S R V J U G Z M C P B T K N D F I L W]
time 2619ms: Process O completed I/O; added to ready queue [Q Q H E S R V J U G Z M C P B T K N D F I L W O]
time 2743ms: Process Y completed I/O; added to ready queue [Q Q H E S R V J U G Z M C P B T K N D F I L W O Y]
time 2750ms: Process A completed a CPU burst; 74 bursts to go [Q Q H E S R V J U G Z M C P B T K N D F I L W O Y]
time 2750ms: Process A switching out of CPU; will block on I/O until time 2767ms [Q Q H E S R V J U G Z M C P B T K N D F I L W O Y]
time 2756ms: Process Q started using the CPU for 42ms burst [Q H E S R V J U G Z M C P B T K N D F I L W O Y]
time 2767ms: Process A completed I/O; added to ready queue [Q H E S R V J U G Z M C P B T K N D F I L W O Y A]
time 2798ms: Process Q completed a CPU burst; 90 bursts to go [Q H E S R V J U G Z M C P B T K N D F I L W O Y A]
time 2798ms: Process Q switching out of CPU; will block on I/O until time 2830ms [Q H E S R V J U G Z M C P B T K N D F I L W O Y A]
time 2804ms: Process H started using the CPU for 95ms burst [Q E S R V J U G Z M C P B T K N D F I L W O Y A]
time 2830ms: Process Q completed I/O; added to ready queue [Q E S R V J U G Z M C P B T K N D F I L W O Y A Q]
time 2899ms: Process H completed a CPU burst; 53 bursts to go [Q E S R V J U G Z M C P B T K N D F I L W O Y A Q]
time 2899ms: Process H switching out of CPU; will block on I/O until time 3055ms [Q E S R V J U G Z M C P B T K N D F I L W O Y A Q]
time 2905ms: Process E started using the CPU for 202ms burst [Q S R V J U G Z M C P B T K N D F I L W O Y A Q]
time 3055ms: Process H completed I/O; added to ready queue [Q S R V J U G Z M C P B T K N D F I L W O Y A Q H]
time 3107ms: Process E terminated [Q S R V J U G Z M C P B T K N D F I L W O Y A Q H]
time 3113ms: Process S started using the CPU for 201ms burst [Q R V J U G Z M C P B T K N D F I L W O Y A Q H]
time 3314ms: Process S completed a CPU burst; 31 bursts to go [Q R V J U G Z M C P B T K N D F I L W O Y A Q H]
time 3314ms: Process S switching out of CPU; will block on I/O until time 3491ms [Q R V J U G Z M C P B T K N D F I L W O Y A Q H]
time 3320ms: Process R started using the CPU for 183ms burst [Q V J U G Z M C P B T K N D F I L W O Y A Q H]
time 3491ms: Process S completed I/O; added to ready queue [Q V J U G Z M C P B T K N D F I L W O Y A Q H S]
time 3503ms: Process R completed a CPU burst; 48 bursts to go [Q V J U G Z M C P B T K N D F I L W O Y A Q H S]
time 3503ms: Process R switching out of CPU; will block on I/O until time 3578ms [Q V J U G Z M C P B T K N D F I L W O Y A Q H S]
time 3509ms: Process V started using the CPU for 127ms burst [Q J U G Z M C P B T K N D F I L W O Y A Q H S]
time 3578ms: Process R completed I/O; added to ready queue [Q J U G Z M C P B T K N D F I L W O Y A Q H S R]
time 3636ms: Process V completed a CPU burst; 30 bursts to go [Q J U G Z M C P B T K N D F I L W O Y A Q H S R]
time 3636ms: Process V switching out of CPU; will block on I/O until time 3653ms [Q J U G Z M C P B T K N D F I L W O Y A Q H S R]
time 3642ms: Process J started using the CPU for 159ms burst [Q U G Z M C P B T K N D F I L W O Y A Q H S R]
time 3653ms: Process V completed I/O; added to ready queue [Q U G Z M C P B T K N D F I L W O Y A Q H S R V]
time 3801ms: Process J completed a CPU burst; 1 burst to go [Q U G Z M C P B T K N D F I L W O Y A Q H S R V]
time 3801ms: Process J switching out of CPU; will block on I/O until time 3907ms [Q U G Z M C P B T K N D F I L W O Y A Q H S R V]
time 3807ms: Process U started using the CPU for 30ms burst [Q G Z M C P B T K N D F I L W O Y A Q H S R V]
time 3837ms: Process U completed a CPU burst; 51 bursts to go [Q G Z M C P B T K N D F I L W O Y A Q H S R V]
time 3837ms: Process U switching out of CPU; will block on I/O until time 3977ms [Q G Z M C P B T K N D F I L W O Y A Q H S R V]
time 3843ms: Process G started using the CPU for 7ms burst [Q Z M C P B T K N D F I L W O Y A Q H S R V]
time 3850ms: Process G completed a CPU burst; 77 bursts to go [Q Z M C P B T K N D F I L W O Y A Q H S R V]
time 3850ms: Process G switching out of CPU; will block on I/O until time 4011ms [Q Z M C P B T K N D F I L W O Y A Q H S R V]
time 3856ms: Process Z started using the CPU for 30ms burst [Q M C P B T K N D F I L W O Y A Q H S R V]
time 3886ms: Process Z completed a CPU burst; 83 bursts to go [Q M C P B T K N D F I L W O Y A Q H S R V]
time 3886ms: Process Z switching out of CPU; will block on I/O until time 3898ms [Q M C P B T K N D F I L W O Y A Q H S R V]
time 3892ms: Process M started using the CPU for 10ms burst [Q C P B T K N D F I L W O Y A Q H S R V]
time 3898ms: Process Z completed I/O; added to ready queue [Q C P B T K N D F I L W O Y A Q H S R V Z]
time 3902ms: Process M completed a CPU burst; 36 bursts to go [Q C P B T K N D F I L W O Y A Q H S R V Z]
time 3902ms: Process M switching out of CPU; will block on I/O until time 4092ms [Q C P B T K N D F I L W O Y A Q H S R V Z]
time 3907ms: Process J completed I/O; added to ready queue [Q P B T K N D F I L W O Y A Q H S R V Z J]
time 3908ms: Process C started using the CPU for 75ms burst [Q P B T K N D F I L W O Y A Q H S R V Z J]
time 3977ms: Process U completed I/O; added to ready queue [Q P B T K N D F I L W O Y A Q H S R V Z J U]
time 3983ms: Process C completed a CPU burst; 56 bursts to go [Q P B T K N D F I L W O Y A Q H S R V Z J U]
time 3983ms: Process C switching out of CPU; will block on I/O until time 4044ms [Q P B T K N D F I L W O Y A Q H S R V Z J U]
time 3989ms: Process P started using the CPU for 13ms burst [Q B T K N D F I L W O Y A Q H S R V Z J U]
time 4002ms: Process P completed a CPU burst; 83 bursts to go [Q B T K N D F I L W O Y A Q H S R V Z J U]
time 4002ms: Process P switching out of CPU; will block on I/O until time 4051ms [Q B T K N D F I L W O Y A Q H S R V Z J U]
time 4008ms: Process B started using the CPU for 111ms burst [Q T K N D F I L W O Y A Q H S R V Z J U]
time 4011ms: Process G completed I/O; added to ready queue [Q T K N D F I L W O Y A Q H S R V Z J U G]
time 4044ms: Process C completed I/O; added to ready queue [Q T K N D F I L W O Y A Q H S R V Z J U G C]
time 4051ms: Process P completed I/O; added to ready queue [Q T K N D F I L W O Y A Q H S R V Z J U G C P]
time 4092ms: Process M completed I/O; added to ready queue [Q T K N D F I L W O Y A Q H S R V Z J U G C P M]
time 4119ms: Process B completed a CPU burst; 83 bursts to go [Q T K N D F I L W O Y A Q H S R V Z J U G C P M]
time 4119ms: Process B switching out of CPU; will block on I/O until time 4145ms [Q T K N D F I L W O Y A Q H S R V Z J U G C P M]
time 4125ms: Process T started using the CPU for 25ms burst [Q K N D F I L W O Y A Q H S R V Z J U G C P M]
time 4145ms: Process B completed I/O; added to ready queue [Q K N D F I L W O Y A Q H S R V Z J U G C P M B]
time 4150ms: Process T completed a CPU burst; 50 bursts to go [Q K N D F I L W O Y A Q H S R V Z J U G C P M B]
time 4150ms: Process T switching out of CPU; will block on I/O until time 4259ms [Q K N D F I L W O Y A Q H S R V Z J U G C P M B]
time 4156ms: Process K started using the CPU for 23ms burst [Q N D F I L W O Y A Q H S R V Z J U G C P M B]
time 4179ms: Process K completed a CPU burst; 86 bursts to go [Q N D F I L W O Y A Q H S R V Z J U G C P M B]
time 4179ms: Process K switching out of CPU; will block on I/O until time 4513ms [Q N D F I L W O Y A Q H S R V Z J U G C P M B]
time 4185ms: Process N started using the CPU for 28ms burst [Q D F I L W O Y A Q H S R V Z J U G C P M B]
time 4213ms: Process N completed a CPU burst; 56 bursts to go [Q D F I L W O Y A Q H S R V Z J U G C P M B]
time 4213ms: Process N switching out of CPU; will block on I/O until time 4223ms [Q D F I L W O Y A Q H S R V Z J U G C P M B]
time 4219ms: Process D started using the CPU for 29ms burst [Q F I L W O Y A Q H S R V Z J U G C P M B]
time 4223ms: Process N completed I/O; added to ready queue [Q F I L W O Y A Q H S R V Z J U G C P M B N]
time 4248ms: Process D completed a CPU burst; 66 bursts to go [Q F I L W O Y A Q H S R V Z J U G C P M B N]
time 4248ms: Process D switching out of CPU; will block on I/O until time 4285ms [Q F I L W O Y A Q H S R V Z J U G C P M B N]
time 4254ms: Process F started using the CPU for 82ms burst [Q I L W O Y A Q H S R V Z J U G C P M B N]
time 4259ms: Process T completed I/O; added to ready queue [Q I L W O Y A Q H S R V Z J U G C P M B N T]
time 4285ms: Process D completed I/O; added to ready queue [Q I L W O Y A Q H S R V Z J U G C P M B N T D]
time 4336ms: Process F completed a CPU burst; 12 bursts to go [Q I L W O Y A Q H S R V Z J U G C P M B N T D]
time 4336ms: Process F switching out of CPU; will block on I/O until time 4454ms [Q I L W O Y A Q H S R V Z J U G C P M B N T D]
time 4342ms: Process I started using the CPU for 188ms burst [Q L W O Y A Q H S R V Z J U G C P M B N T D]
time 4454ms: Process F completed I/O; added to ready queue [Q L W O Y A Q H S R V Z J U G C P M B N T D F]
time 4513ms: Process K completed I/O; added to ready queue [Q L W O Y A Q H S R V Z J U G C P M B N T D F K]
time 4530ms: Process I completed a CPU burst; 57 bursts to go [Q L W O Y A Q H S R V Z J U G C P M B N T D F K]
time 4530ms: Process I switching out of CPU; will block on I/O until time 4551ms [Q L W O Y A Q H S R V Z J U G C P M B N T D F K]
time 4536ms: Process L started using the CPU for 43ms burst [Q W O Y A Q H S R V Z J U G C P M B N T D F K]
time 4551ms: Process I completed I/O; added to ready queue [Q W O Y A Q H S R V Z J U G C P M B N T D F K I]
time 4579ms: Process L completed a CPU burst; 23 bursts to go [Q W O Y A Q H S R V Z J U G C P M B N T D F K I]
time 4579ms: Process L switching out of CPU; will block on I/O until time 4628ms [Q W O Y A Q H S R V Z J U G C P M B N T D F K I]
time 4585ms: Process W started using the CPU for 8ms burst [Q O Y A Q H S R V Z J U G C P M B N T D F K I]
time 4593ms: Process W completed a CPU burst; 21 bursts to go [Q O Y A Q H S R V Z J U G C P M B N T D F K I]
time 4593ms: Process W switching out of CPU; will block on I/O until time 4757ms [Q O Y A Q H S R V Z J U G C P M B N T D F K I]
time 4599ms: Process O started using the CPU for 198ms burst [Q Y A Q H S R V Z J U G C P M B N T D F K I]
time 4628ms: Process L completed I/O; added to ready queue [Q Y A Q H S R V Z J U G C P M B N T D F K I L]
time 4757ms: Process W completed I/O; added to ready queue [Q Y A Q H S R V Z J U G C P M B N T D F K I L W]
time 4797ms: Process O completed a CPU burst; 54 bursts to go [Q Y A Q H S R V Z J U G C P M B N T D F K I L W]
time 4797ms: Process O switching out of CPU; will block on I/O until time 4824ms [Q Y A Q H S R V Z J U G C P M B N T D F K I L W]
time 4803ms: Process Y started using the CPU for 190ms burst [Q A Q H S R V Z J U G C P M B N T D F K I L W]
time 4824ms: Process O completed I/O; added to ready queue [Q A Q H S R V Z J U G C P M B N T D F K I L W O]
time 4993ms: Process Y completed a CPU burst; 28 bursts to go [Q A Q H S R V Z J U G C P M B N T D F K I L W O]
time 4993ms: Process Y switching out of CPU; will block on I/O until time 5101ms [Q A Q H S R V Z J U G C P M B N T D F K I L W O]
time 4999ms: Process A started using the CPU for 55ms burst [Q Q H S R V Z J U G C P M B N T D F K I L W O]
time 5054ms: Process A completed a CPU burst; 73 bursts to go [Q Q H S R V Z J U G C P M B N T D F K I L W O]
time 5054ms: Process A switching out of CPU; will block on I/O until time 5082ms [Q Q H S R V Z J U G C P M B N T D F K I L W O]
time 5060ms: Process Q started using the CPU for 59ms burst [Q H S R V Z J U G C P M B N T D F K I L W O]
time 5082ms: Process A completed I/O; added to ready queue [Q H S R V Z J U G C P M B N T D F K I L W O A]
time 5101ms: Process Y completed I/O; added to ready queue [Q H S R V Z J U G C P M B N T D F K I L W O A Y]
time 5119ms: Process Q completed a CPU burst; 89 bursts to go [Q H S R V Z J U G C P M B N T D F K I L W O A Y]
time 5119ms: Process Q switching out of CPU; will block on I/O until time 5159ms [Q H S R V Z J U G C P M B N T D F K I L W O A Y]
time 5125ms: Process H started using the CPU for 94ms burst [Q S R V Z J U G C P M B N T D F K I L W O A Y]
time 5159ms: Process Q completed I/O; added to ready queue [Q S R V Z J U G C P M B N T D F K I L W O A Y Q]
time 5219ms: Process H completed a CPU burst; 52 bursts to go [Q S R V Z J U G C P M B N T D F K I L W O A Y Q]
time 5219ms: Process H switching out of CPU; will block on I/O until time 5386ms [Q S R V Z J U G C P M B N T D F K I L W O A Y Q]
time 5225ms: Process S started using the CPU for 5ms burst [Q R V Z J U G C P M B N T D F K I L W O A Y Q]
time 5230ms: Process S completed a CPU burst; 30 bursts to go [Q R V Z J U G C P M B N T D F K I L W O A Y Q]
time 5230ms: Process S switching out of CPU; will block on I/O until time 5247ms [Q R V Z J U G C P M B N T D F K I L W O A Y Q]
time 5236ms: Process R started using the CPU for 54ms burst [Q V Z J U G C P M B N T D F K I L W O A Y Q]
time 5247ms: Process S completed I/O; added to ready queue [Q V Z J U G C P M B N T D F K I L W O A Y Q S]
time 5290ms: Process R completed a CPU burst; 47 bursts to go [Q V Z J U G C P M B N T D F K I L W O A Y Q S]
time 5290ms: Process R switching out of CPU; will block on I/O until time 5837ms [Q V Z J U G C P M B N T D F K I L W O A Y Q S]
time 5296ms: Process V started using the CPU for 201ms burst [Q Z J U G C P M B N T D F K I L W O A Y Q S]
time 5386ms: Process H completed I/O; added to ready queue [Q Z J U G C P M B N T D F K I L W O A Y Q S H]
time 5497ms: Process V completed a CPU burst; 29 bursts to go [Q Z J U G C P M B N T D F K I L W O A Y Q S H]
time 5497ms: Process V switching out of CPU; will block on I/O until time 5549ms [Q Z J U G C P M B N T D F K I L W O A Y Q S H]
time 5503ms: Process Z started using the CPU for 5ms burst [Q J U G C P M B N T D F K I L W O A Y Q S H]
time 5508ms: Process Z completed a CPU burst; 82 bursts to go [Q J U G C P M B N T D F K I L W O A Y Q S H]
time 5508ms: Process Z switching out of CPU; will block on I/O until time 5513ms [Q J U G C P M B N T D F K I L W O A Y Q S H]
time 5513ms: Process Z completed I/O; added to ready queue [Q U G C P M B N T D F K I L W O A Y Q S H Z]
time 5514ms: Process J started using the CPU for 104ms burst [Q U G C P M B N T D F K I L W O A Y Q S H Z]
time 5549ms: Process V completed I/O; added to ready queue [Q U G C P M B N T D F K I L W O A Y Q S H Z V]
time 5618ms: Process J terminated [Q U G C P M B N T D F K I L W O A Y Q S H Z V]
time 5624ms: Process U started using the CPU for 197ms burst [Q G C P M B N T D F K I L W O A Y Q S H Z V]
time 5821ms: Process U completed a CPU burst; 50 bursts to go [Q G C P M B N T D F K I L W O A Y Q S H Z V]
time 5821ms: Process U switching out of CPU; will block on I/O until time 5992ms [Q G C P M B N T D F K I L W O A Y Q S H Z V]
time 5827ms: Process G started using the CPU for 33ms burst [Q C P M B N T D F K I L W O A Y Q S H Z V]
time 5837ms: Process R completed I/O; added to ready queue [Q C P M B N T D F K I L W O A Y Q S H Z V R]
time 5860ms: Process G completed a CPU burst; 76 bursts to go [Q C P M B N T D F K I L W O A Y Q S H Z V R]
time 5860ms: Process G switching out of CPU; will block on I/O until time 5881ms [Q C P M B N T D F K I L W O A Y Q S H Z V R]
time 5866ms: Process C started using the CPU for 179ms burst [Q P M B N T D F K I L W O A Y Q S H Z V R]
time 5881ms: Process G completed I/O; added to ready queue [Q P M B N T D F K I L W O A Y Q S H Z V R G]
time 5992ms: Process U completed I/O; added to ready queue [Q P M B N T D F K I L W O A Y Q S H Z V R G U]
time 6045ms: Process C completed a CPU burst; 55 bursts to go [Q P M B N T D F K I L W O A Y Q S H Z V R G U]
time 6045ms: Process C switching out of CPU; will block on I/O until time 6098ms [Q P M B N T D F K I L W O A Y Q S H Z V R G U]
time 6051ms: Process P started using the CPU for 327ms burst [Q M B N T D F K I L W O A Y Q S H Z V R G U]
time 6098ms: Process C completed I/O; added to ready queue [Q M B N T D F K I L W O A Y Q S H Z V R G U C]
time 6378ms: Process P completed a CPU burst; 82 bursts to go [Q M B N T D F K I L W O A Y Q S H Z V R G U C]
time 6378ms: Process P switching out of CPU; will block on I/O until time 6478ms [Q M B N T D F K I L W O A Y Q S H Z V R G U C]
time 6384ms: Process M started using the CPU for 14ms burst [Q B N T D F K I L W O A Y Q S H Z V R G U C]
time 6398ms: Process M completed a CPU burst; 35 bursts to go [Q B N T D F K I L W O A Y Q S H Z V R G U C]
time 6398ms: Process M switching out of CPU; will block on I/O until time 6625ms [Q B N T D F K I L W O A Y Q S H Z V R G U C]
time 6404ms: Process B started using the CPU for 184ms burst [Q N T D F K I L W O A Y Q S H Z V R G U C]
time 6478ms: Process P completed I/O; added to ready queue [Q N T D F K I L W O A Y Q S H Z V R G U C P]
time 6588ms: Process B completed a CPU burst; 82 bursts to go [Q N T D F K I L W O A Y Q S H Z V R G U C P]
time 6588ms: Process B switching out of CPU; will block on I/O until time 6606ms [Q N T D F K I L W O A Y Q S H Z V R G U C P]
time 6594ms: Process N started using the CPU for 75ms burst [Q T D F K I L W O A Y Q S H Z V R G U C P]
time 6606ms: Process B completed I/O; added to ready queue [Q T D F K I L W O A Y Q S H Z V R G U C P B]
time 6625ms: Process M completed I/O; added to ready queue [Q T D F K I L W O A Y Q S H Z V R G U C P B M]
time 6669ms: Process N completed a CPU burst; 55 bursts to go [Q T D F K I L W O A Y Q S H Z V R G U C P B M]
time 6669ms: Process N switching out of CPU; will block on I/O until time 6789ms [Q T D F K I L W O A Y Q S H Z V R G U C P B M]
time 6675ms: Process T started using the CPU for 22ms burst [Q D F K I L W O A Y Q S H Z V R G U C P B M]
time 6697ms: Process T completed a CPU burst; 49 bursts to go [Q D F K I L W O A Y Q S H Z V R G U C P B M]
time 6697ms: Process T switching out of CPU; will block on I/O until time 6760ms [Q D F K I L W O A Y Q S H Z V R G U C P B M]
time 6703ms: Process D started using the CPU for 245ms burst [Q F K I L W O A Y Q S H Z V R G U C P B M]
time 6760ms: Process T completed I/O; added to ready queue [Q F K I L W O A Y Q S H Z V R G U C P B M T]
time 6789ms: Process N completed I/O; added to ready queue [Q F K I L W O A Y Q S H Z V R G U C P B M T N]
time 6948ms: Process D completed a CPU burst; 65 bursts to go [Q F K I L W O A Y Q S H Z V R G U C P B M T N]
time 6948ms: Process D switching out of CPU; will block on I/O until time 6974ms [Q F K I L W O A Y Q S H Z V R G U C P B M T N]
time 6954ms: Process F started using the CPU for 85ms burst [Q K I L W O A Y Q S H Z V R G U C P B M T N]
time 6974ms: Process D completed I/O; added to ready queue [Q K I L W O A Y Q S H Z V R G U C P B M T N D]
time 7039ms: Process F completed a CPU burst; 11 bursts to go [Q K I L W O A Y Q S H Z V R G U C P B M T N D]
time 7039ms: Process F switching out of CPU; will block on I/O until time 7046ms [Q K I L W O A Y Q S H Z V R G U C P B M T N D]
time 7045ms: Process K started using the CPU for 97ms burst [Q I L W O A Y Q S H Z V R G U C P B M T N D]
time 7046ms: Process F completed I/O; added to ready queue [Q I L W O A Y Q S H Z V R G U C P B M T N D F]
time 7142ms: Process K completed a CPU burst; 85 bursts to go [Q I L W O A Y Q S H Z V R G U C P B M T N D F]
time 7142ms: Process K switching out of CPU; will block on I/O until time 7146ms [Q I L W O A Y Q S H Z V R G U C P B M T N D F]
time 7146ms: Process K completed I/O; added to ready queue [Q L W O A Y Q S H Z V R G U C P B M T N D F K]
time 7148ms: Process I started using the CPU for 89ms burst [Q L W O A Y Q S H Z V R G U C P B M T N D F K]
time 7237ms: Process I completed a CPU burst; 56 bursts to go [Q L W O A Y Q S H Z V R G U C P B M T N D F K]
time 7237ms: Process I switching out of CPU; will block on I/O until time 7519ms [Q L W O A Y Q S H Z V R G U C P B M T N D F K]
time 7243ms: Process L started using the CPU for 9ms burst [Q W O A Y Q S H Z V R G U C P B M T N D F K]
time 7252ms: Process L completed a CPU burst; 22 bursts to go [Q W O A Y Q S H Z V R G U C P B M T N D F K]
time 7252ms: Process L switching out of CPU; will block on I/O until time 7299ms [Q W O A Y Q S H Z V R G U C P B M T N D F K]
time 7258ms: Process W started using the CPU for 105ms burst [Q O A Y Q S H Z V R G U C P B M T N D F K]
time 7299ms: Process L completed I/O; added to ready queue [Q O A Y Q S H Z V R G U C P B M T N D F K L]
time 7363ms: Process W completed a CPU burst; 20 bursts to go [Q O A Y Q S H Z V R G U C P B M T N D F K L]
time 7363ms: Process W switching out of CPU; will block on I/O until time 7372ms [Q O A Y Q S H Z V R G U C P B M T N D F K L]
time 7369ms: Process O started using the CPU for 43ms burst [Q A Y Q S H Z V R G U C P B M T N D F K L]
time 7372ms: Process W completed I/O; added to ready queue [Q A Y Q S H Z V R G U C P B M T N D F K L W]
time 7412ms: Process O completed a CPU burst; 53 bursts to go [Q A Y Q S H Z V R G U C P B M T N D F K L W]
time 7412ms: Process O switching out of CPU; will block on I/O until time 7479ms [Q A Y Q S H Z V R G U C P B M T N D F K L W]
time 7418ms: Process A started using the CPU for 37ms burst [Q Y Q S H Z V R G U C P B M T N D F K L W]
time 7455ms: Process A completed a CPU burst; 72 bursts to go [Q Y Q S H Z V R G U C P B M T N D F K L W]
time 7455ms: Process A switching out of CPU; will block on I/O until time 7558ms [Q Y Q S H Z V R G U C P B M T N D F K L W]
time 7461ms: Process Y started using the CPU for 162ms burst [Q Q S H Z V R G U C P B M T N D F K L W]
time 7479ms: Process O completed I/O; added to ready queue [Q Q S H Z V R G U C P B M T N D F K L W O]
time 7519ms: Process I completed I/O; added to ready queue [Q Q S H Z V R G U C P B M T N D F K L W O I]
time 7558ms: Process A completed I/O; added to ready queue [Q Q S H Z V R G U C P B M T N D F K L W O I A]
time 7623ms: Process Y completed a CPU burst; 27 bursts to go [Q Q S H Z V R G U C P B M T N D F K L W O I A]
time 7623ms: Process Y switching out of CPU; will block on I/O until time 7749ms [Q Q S H Z V R G U C P B M T N D F K L W O I A]
time 7629ms: Process Q started using the CPU for 25ms burst [Q S H Z V R G U C P B M T N D F K L W O I A]
time 7654ms: Process Q completed a CPU burst; 88 bursts to go [Q S H Z V R G U C P B M T N D F K L W O I A]
time 7654ms: Process Q switching out of CPU; will block on I/O until time 7731ms [Q S H Z V R G U C P B M T N D F K L W O I A]
time 7660ms: Process S started using the CPU for 5ms burst [Q H Z V R G U C P B M T N D F K L W O I A]
time 7665ms: Process S completed a CPU burst; 29 bursts to go [Q H Z V R G U C P B M T N D F K L W O I A]
time 7665ms: Process S switching out of CPU; will block on I/O until time 7670ms [Q H Z V R G U C P B M T N D F K L W O I A]
time 7670ms: Process S completed I/O; added to ready queue [Q Z V R G U C P B M T N D F K L W O I A S]
time 7671ms: Process H started using the CPU for 5ms burst [Q Z V R G U C P B M T N D F K L W O I A S]
time 7676ms: Process H completed a CPU burst; 51 bursts to go [Q Z V R G U C P B M T N D F K L W O I A S]
time 7676ms: Process H switching out of CPU; will block on I/O until time 7741ms [Q Z V R G U C P B M T N D F K L W O I A S]
time 7682ms: Process Z started using the CPU for 208ms burst [Q V R G U C P B M T N D F K L W O I A S]
time 7731ms: Process Q completed I/O; added to ready queue [Q V R G U C P B M T N D F K L W O I A S Q]
time 7741ms: Process H completed I/O; added to ready queue [Q V R G U C P B M T N D F K L W O I A S Q H]
time 7749ms: Process Y completed I/O; added to ready queue [Q V R G U C P B M T N D F K L W O I A S Q H Y]
time 7890ms: Process Z completed a CPU burst; 81 bursts to go [Q V R G U C P B M T N D F K L W O I A S Q H Y]
time 7890ms: Process Z switching out of CPU; will block on I/O until time 7943ms [Q V R G U C P B M T N D F K L W O I A S Q H Y]
time 7896ms: Process V started using the CPU for 198ms burst [Q R G U C P B M T N D F K L W O I A S Q H Y]
time 7943ms: Process Z completed I/O; added to ready queue [Q R G U C P B M T N D F K L W O I A S Q H Y Z]
time 8094ms: Process V completed a CPU burst; 28 bursts to go [Q R G U C P B M T N D F K L W O I A S Q H Y Z]
time 8094ms: Process V switching out of CPU; will block on I/O until time 8330ms [Q R G U C P B M T N D F K L W O I A S Q H Y Z]
time 8100ms: Process R started using the CPU for 11ms burst [Q G U C P B M T N D F K L W O I A S Q H Y Z]
time 8111ms: Process R completed a CPU burst; 46 bursts to go [Q G U C P B M T N D F K L W O I A S Q H Y Z]
time 8111ms: Process R switching out of CPU; will block on I/O until time 8205ms [Q G U C P B M T N D F K L W O I A S Q H Y Z]
time 8117ms: Process G started using the CPU for 107ms burst [Q U C P B M T N D F K L W O I A S Q H Y Z]
time 8205ms: Process R completed I/O; added to ready queue [Q U C P B M T N D F K L W O I A S Q H Y Z R]
time 8224ms: Process G completed a CPU burst; 75 bursts to go [Q U C P B M T N D F K L W O I A S Q H Y Z R]
time 8224ms: Process G switching out of CPU; will block on I/O until time 8339ms [Q U C P B M T N D F K L W O I A S Q H Y Z R]
time 8230ms: Process U started using the CPU for 3ms burst [Q C P B M T N D F K L W O I A S Q H Y Z R]
time 8233ms: Process U completed a CPU burst; 49 bursts to go [Q C P B M T N D F K L W O I A S Q H Y Z R]
time 8233ms: Process U switching out of CPU; will block on I/O until time 8325ms [Q C P B M T N D F K L W O I A S Q H Y Z R]
time 8239ms: Process C started using the CPU for 45ms burst [Q P B M T N D F K L W O I A S Q H Y Z R]
time 8284ms: Process C completed a CPU burst; 54 bursts to go [Q P B M T N D F K L W O I A S Q H Y Z R]
time 8284ms: Process C switching out of CPU; will block on I/O until time 8406ms [Q P B M T N D F K L W O I A S Q H Y Z R]
time 8290ms: Process P started using the CPU for 162ms burst [Q B M T N D F K L W O I A S Q H Y Z R]
time 8325ms: Process U completed I/O; added to ready queue [Q B M T N D F K L W O I A S Q H Y Z R U]
time 8330ms: Process V completed I/O; added to ready queue [Q B M T N D F K L W O I A S Q H Y Z R U V]
time 8339ms: Process G completed I/O; added to ready queue [Q B M T N D F K L W O I A S Q H Y Z R U V G]
time 8406ms: Process C completed I/O; added to ready queue [Q B M T N D F K L W O I A S Q H Y Z R U V G C]
time 8452ms: Process P completed a CPU burst; 81 bursts to go [Q B M T N D F K L W O I A S Q H Y Z R U V G C]
time 8452ms: Process P switching out of CPU; will block on I/O until time 8702ms [Q B M T N D F K L W O I A S Q H Y Z R U V G C]
time 8458ms: Process B started using the CPU for 51ms burst [Q M T N D F K L W O I A S Q H Y Z R U V G C]
time 8509ms: Process B completed a CPU burst; 81 bursts to go [Q M T N D F K L W O I A S Q H Y Z R U V G C]
time 8509ms: Process B switching out of CPU; will block on I/O until time 8599ms [Q M T N D F K L W O I A S Q H Y Z R U V G C]
time 8515ms: Process M started using the CPU for 102ms burst [Q T N D F K L W O I A S Q H Y Z R U V G C]
time 8599ms: Process B completed I/O; added to ready queue [Q T N D F K L W O I A S Q H Y Z R U V G C B]
time 8617ms: Process M completed a CPU burst; 34 bursts to go [Q T N D F K L W O I A S Q H Y Z R U V G C B]
time 8617ms: Process M switching out of CPU; will block on I/O until time 9158ms [Q T N D F K L W O I A S Q H Y Z R U V G C B]
time 8623ms: Process T started using the CPU for 5ms burst [Q N D F K L W O I A S Q H Y Z R U V G C B]
time 8628ms: Process T completed a CPU burst; 48 bursts to go [Q N D F K L W O I A S Q H Y Z R U V G C B]
time 8628ms: Process T switching out of CPU; will block on I/O until time 8655ms [Q N D F K L W O I A S Q H Y Z R U V G C B]
time 8634ms: Process N started using the CPU for 25ms burst [Q D F K L W O I A S Q H Y Z R U V G C B]
time 8655ms: Process T completed I/O; added to ready queue [Q D F K L W O I A S Q H Y Z R U V G C B T]
time 8659ms: Process N completed a CPU burst; 54 bursts to go [Q D F K L W O I A S Q H Y Z R U V G C B T]
time 8659ms: Process N switching out of CPU; will block on I/O until time 8667ms [Q D F K L W O I A S Q H Y Z R U V G C B T]
time 8665ms: Process D started using the CPU for 99ms burst [Q F K L W O I A S Q H Y Z R U V G C B T]
time 8667ms: Process N completed I/O; added to ready queue [Q F K L W O I A S Q H Y Z R U V G C B T N]
time 8702ms: Process P completed I/O; added to ready queue [Q F K L W O I A S Q H Y Z R U V G C B T N P]
time 8764ms: Process D completed a CPU burst; 64 bursts to go [Q F K L W O I A S Q H Y Z R U V G C B T N P]
time 8764ms: Process D switching out of CPU; will block on I/O until time 8846ms [Q F K L W O I A S Q H Y Z R U V G C B T N P]
time 8770ms: Process F started using the CPU for 22ms burst [Q K L W O I A S Q H Y Z R U V G C B T N P]
time 8792ms: Process F completed a CPU burst; 10 bursts to go [Q K L W O I A S Q H Y Z R U V G C B T N P]
time 8792ms: Process F switching out of CPU; will block on I/O until time 8828ms [Q K L W O I A S Q H Y Z R U V G C B T N P]
time 8798ms: Process K started using the CPU for 76ms burst [Q L W O I A S Q H Y Z R U V G C B T N P]
time 8828ms: Process F completed I/O; added to ready queue [Q L W O I A S Q H Y Z R U V G C B T N P F]
time 8846ms: Process D completed I/O; added to ready queue [Q L W O I A S Q H Y Z R U V G C B T N P F D]
time 8874ms: Process K completed a CPU burst; 84 bursts to go [Q L W O I A S Q H Y Z R U V G C B T N P F D]
time 8874ms: Process K switching out of CPU; will block on I/O until time 8931ms [Q L W O I A S Q H Y Z R U V G C B T N P F D]
time 8880ms: Process L started using the CPU for 66ms burst [Q W O I A S Q H Y Z R U V G C B T N P F D]
time 8931ms: Process K completed I/O; added to ready queue [Q W O I A S Q H Y Z R U V G C B T N P F D K]
time 8946ms: Process L completed a CPU burst; 21 bursts to go [Q W O I A S Q H Y Z R U V G C B T N P F D K]
time 8946ms: Process L switching out of CPU; will block on I/O until time 8957ms [Q W O I A S Q H Y Z R U V G C B T N P F D K]
time 8952ms: Process W started using the CPU for 189ms burst [Q O I A S Q H Y Z R U V G C B T N P F D K]
time 8957ms: Process L completed I/O; added to ready queue [Q O I A S Q H Y Z R U V G C B T N P F D K L]
time 9141ms: Process W completed a CPU burst; 19 bursts to go [Q O I A S Q H Y Z R U V G C B T N P F D K L]
time 9141ms: Process W switching out of CPU; will block on I/O until time 9251ms [Q O I A S Q H Y Z R U V G C B T N P F D K L]
time 9147ms: Process O started using the CPU for 7ms burst [Q I A S Q H Y Z R U V G C B T N P F D K L]
time 9154ms: Process O completed a CPU burst; 52 bursts to go [Q I A S Q H Y Z R U V G C B T N P F D K L]
time 9154ms: Process O switching out of CPU; will block on I/O until time 9333ms [Q I A S Q H Y Z R U V G C B T N P F D K L]
time 9158ms: Process M completed I/O; added to ready queue [Q A S Q H Y Z R U V G C B T N P F D K L M]
time 9160ms: Process I started using the CPU for 190ms burst [Q A S Q H Y Z R U V G C B T N P F D K L M]
time 9251ms: Process W completed I/O; added to ready queue [Q A S Q H Y Z R U V G C B T N P F D K L M W]
time 9333ms: Process O completed I/O; added to ready queue [Q A S Q H Y Z R U V G C B T N P F D K L M W O]
time 9350ms: Process I completed a CPU burst; 55 bursts to go [Q A S Q H Y Z R U V G C B T N P F D K L M W O]
time 9350ms: Process I switching out of CPU; will block on I/O until time 9364ms [Q A S Q H Y Z R U V G C B T N P F D K L M W O]
time 9356ms: Process A started using the CPU for 14ms burst [Q S Q H Y Z R U V G C B T N P F D K L M W O]
time 9364ms: Process I completed I/O; added to ready queue [Q S Q H Y Z R U V G C B T N P F D K L M W O I]
time 9370ms: Process A completed a CPU burst; 71 bursts to go [Q S Q H Y Z R U V G C B T N P F D K L M W O I]
time 9370ms: Process A switching out of CPU; will block on I/O until time 9403ms [Q S Q H Y Z R U V G C B T N P F D K L M W O I]
time 9376ms: Process S started using the CPU for 139ms burst [Q Q H Y Z R U V G C B T N P F D K L M W O I]
time 9403ms: Process A completed I/O; added to ready queue [Q Q H Y Z R U V G C B T N P F D K L M W O I A]
time 9515ms: Process S completed a CPU burst; 28 bursts to go [Q Q H Y Z R U V G C B T N P F D K L M W O I A]
time 9515ms: Process S switching out of CPU; will block on I/O until time 9715ms [Q Q H Y Z R U V G C B T N P F D K L M W O I A]
time 9521ms: Process Q started using the CPU for 16ms burst [Q H Y Z R U V G C B T N P F D K L M W O I A]
time 9537ms: Process Q completed a CPU burst; 87 bursts to go [Q H Y Z R U V G C B T N P F D K L M W O I A]
time 9537ms: Process Q switching out of CPU; will block on I/O until time 9584ms [Q H Y Z R U V G C B T N P F D K L M W O I A]
time 9543ms: Process H started using the CPU for 35ms burst [Q Y Z R U V G C B T N P F D K L M W O I A]
time 9578ms: Process H completed a CPU burst; 50 bursts to go [Q Y Z R U V G C B T N P F D K L M W O I A]
time 9578ms: Process H switching out of CPU; will block on I/O until time 9691ms [Q Y Z R U V G C B T N P F D K L M W O I A]
time 9584ms: Process Y started using the CPU for 5ms burst [Q Z R U V G C B T N P F D K L M W O I A]
time 9584ms: Process Q completed I/O; added to ready queue [Q Z R U V G C B T N P F D K L M W O I A Q]
time 9589ms: Process Y completed a CPU burst; 26 bursts to go [Q Z R U V G C B T N P F D K L M W O I A Q]
time 9589ms: Process Y switching out of CPU; will block on I/O until time 9617ms [Q Z R U V G C B T N P F D K L M W O I A Q]
time 9595ms: Process Z started using the CPU for 86ms burst [Q R U V G C B T N P F D K L M W O I A Q]
time 9617ms: Process Y completed I/O; added to ready queue [Q R U V G C B T N P F D K L M W O I A Q Y]
time 9681ms: Process Z completed a CPU burst; 80 bursts to go [Q R U V G C B T N P F D K L M W O I A Q Y]
time 9681ms: Process Z switching out of CPU; will block on I/O until time 9697ms [Q R U V G C B T N P F D K L M W O I A Q Y]
time 9687ms: Process R started using the CPU for 152ms burst [Q U V G C B T N P F D K L M W O I A Q Y]
time 9691ms: Process H completed I/O; added to ready queue [Q U V G C B T N P F D K L M W O I A Q Y H]
time 9697ms: Process Z completed I/O; added to ready queue [Q U V G C B T N P F D K L M W O I A Q Y H Z]
time 9715ms: Process S completed I/O; added to ready queue [Q U V G C B T N P F D K L M W O I A Q Y H Z S]
time 9839ms: Process R completed a CPU burst; 45 bursts to go [Q U V G C B T N P F D K L M W O I A Q Y H Z S]
time 9839ms: Process R switching out of CPU; will block on I/O until time 9879ms [Q U V G C B T N P F D K L M W O I A Q Y H Z S]
time 9845ms: Process U started using the CPU for 261ms burst [Q V G C B T N P F D K L M W O I A Q Y H Z S]
time 9879ms: Process R completed I/O; added to ready queue [Q V G C B T N P F D K L M W O I A Q Y H Z S R]
time 10106ms: Process U completed a CPU burst; 48 bursts to go [Q V G C B T N P F D K L M W O I A Q Y H Z S R]
time 10106ms: Process U switching out of CPU; will block on I/O until time 10184ms [Q V G C B T N P F D K L M W O I A Q Y H Z S R]
time 10112ms: Process V started using the CPU for 63ms burst [Q G C B T N P F D K L M W O I A Q Y H Z S R]
time 10175ms: Process V completed a CPU burst; 27 bursts to go [Q G C B T N P F D K L M W O I A Q Y H Z S R]
time 10175ms: Process V switching out of CPU; will block on I/O until time 10228ms [Q G C B T N P F D K L M W O I A Q Y H Z S R]
time 10181ms: Process G started using the CPU for 109ms burst [Q C B T N P F D K L M W O I A Q Y H Z S R]
time 10184ms: Process U completed I/O; added to ready queue [Q C B T N P F D K L M W O I A Q Y H Z S R U]
time 10228ms: Process V completed I/O; added to ready queue [Q C B T N P F D K L M W O I A Q Y H Z S R U V]
time 10290ms: Process G completed a CPU burst; 74 bursts to go [Q C B T N P F D K L M W O I A Q Y H Z S R U V]
time 10290ms: Process G switching out of CPU; will block on I/O until time 10357ms [Q C B T N P F D K L M W O I A Q Y H Z S R U V]
time 10296ms: Process C started using the CPU for 5ms burst [Q B T N P F D K L M W O I A Q Y H Z S R U V]
time 10301ms: Process C completed a CPU burst; 53 bursts to go [Q B T N P F D K L M W O I A Q Y H Z S R U V]
time 10301ms: Process C switching out of CPU; will block on I/O until time 10331ms [Q B T N P F D K L M W O I A Q Y H Z S R U V]
time 10307ms: Process B started using the CPU for 2ms burst [Q T N P F D K L M W O I A Q Y H Z S R U V]
time 10309ms: Process B completed a CPU burst; 80 bursts to go [Q T N P F D K L M W O I A Q Y H Z S R U V]
time 10309ms: Process B switching out of CPU; will block on I/O until time 10327ms [Q T N P F D K L M W O I A Q Y H Z S R U V]
time 10315ms: Process T started using the CPU for 23ms burst [Q N P F D K L M W O I A Q Y H Z S R U V]
time 10327ms: Process B completed I/O; added to ready queue [Q N P F D K L M W O I A Q Y H Z S R U V B]
time 10331ms: Process C completed I/O; added to ready queue [Q N P F D K L M W O I A Q Y H Z S R U V B C]
time 10338ms: Process T completed a CPU burst; 47 bursts to go [Q N P F D K L M W O I A Q Y H Z S R U V B C]
time 10338ms: Process T switching out of CPU; will block on I/O until time 10355ms [Q N P F D K L M W O I A Q Y H Z S R U V B C]
time 10344ms: Process N started using the CPU for 95ms burst [Q P F D K L M W O I A Q Y H Z S R U V B C]
time 10355ms: Process T completed I/O; added to ready queue [Q P F D K L M W O I A Q Y H Z S R U V B C T]
time 10357ms: Process G completed I/O; added to ready queue [Q P F D K L M W O I A Q Y H Z S R U V B C T G]
time 10439ms: Process N completed a CPU burst; 53 bursts to go [Q P F D K L M W O I A Q Y H Z S R U V B C T G]
time 10439ms: Process N switching out of CPU; will block on I/O until time 10515ms [Q P F D K L M W O I A Q Y H Z S R U V B C T G]
time 10445ms: Process P started using the CPU for 73ms burst [Q F D K L M W O I A Q Y H Z S R U V B C T G]
time 10515ms: Process N completed I/O; added to ready queue [Q F D K L M W O I A Q Y H Z S R U V B C T G N]
time 10518ms: Process P completed a CPU burst; 80 bursts to go [Q F D K L M W O I A Q Y H Z S R U V B C T G N]
time 10518ms: Process P switching out of CPU; will block on I/O until time 10579ms [Q F D K L M W O I A Q Y H Z S R U V B C T G N]
time 10524ms: Process F started using the CPU for 17ms burst [Q D K L M W O I A Q Y H Z S R U V B C T G N]
time 10541ms: Process F completed a CPU burst; 9 bursts to go [Q D K L M W O I A Q Y H Z S R U V B C T G N]
time 10541ms: Process F switching out of CPU; will block on I/O until time 10552ms [Q D K L M W O I A Q Y H Z S R U V B C T G N]
time 10547ms: Process D started using the CPU for 102ms burst [Q K L M W O I A Q Y H Z S R U V B C T G N]
time 10552ms: Process F completed I/O; added to ready queue [Q K L M W O I A Q Y H Z S R U V B C T G N F]
time 10579ms: Process P completed I/O; added to ready queue [Q K L M W O I A Q Y H Z S R U V B C T G N F P]
time 10649ms: Process D completed a CPU burst; 63 bursts to go [Q K L M W O I A Q Y H Z S R U V B C T G N F P]
time 10649ms: Process D switching out of CPU; will block on I/O until time 10678ms [Q K L M W O I A Q Y H Z S R U V B C T G N F P]
time 10655ms: Process K started using the CPU for 408ms burst [Q L M W O I A Q Y H Z S R U V B C T G N F P]
time 10678ms: Process D completed I/O; added to ready queue [Q L M W O I A Q Y H Z S R U V B C T G N F P D]
time 11063ms: Process K completed a CPU burst; 83 bursts to go [Q L M W O I A Q Y H Z S R U V B C T G N F P D]
time 11063ms: Process K switching out of CPU; will block on I/O until time 11067ms [Q L M W O I A Q Y H Z S R U V B C T G N F P D]
time 11067ms: Process K completed I/O; added to ready queue [Q M W O I A Q Y H Z S R U V B C T G N F P D K]
time 11069ms: Process L started using the CPU for 34ms burst [Q M W O I A Q Y H Z S R U V B C T G N F P D K]
time 11103ms: Process L completed a CPU burst; 20 bursts to go [Q M W O I A Q Y H Z S R U V B C T G N F P D K]
time 11103ms: Process L switching out of CPU; will block on I/O until time 11167ms [Q M W O I A Q Y H Z S R U V B C T G N F P D K]
time 11109ms: Process M started using the CPU for 13ms burst [Q W O I A Q Y H Z S R U V B C T G N F P D K]
time 11122ms: Process M completed a CPU burst; 33 bursts to go [Q W O I A Q Y H Z S R U V B C T G N F P D K]
time 11122ms: Process M switching out of CPU; will block on I/O until time 11163ms [Q W O I A Q Y H Z S R U V B C T G N F P D K]
time 11128ms: Process W started using the CPU for 133ms burst [Q O I A Q Y H Z S R U V B C T G N F P D K]
time 11163ms: Process M completed I/O; added to ready queue [Q O I A Q Y H Z S R U V B C T G N F P D K M]
time 11167ms: Process L completed I/O; added to ready queue [Q O I A Q Y H Z S R U V B C T G N F P D K M L]
time 11261ms: Process W completed a CPU burst; 18 bursts to go [Q O I A Q Y H Z S R U V B C T G N F P D K M L]
time 11261ms: Process W switching out of CPU; will block on I/O until time 11327ms [Q O I A Q Y H Z S R U V B C T G N F P D K M L]
time 11267ms: Process O started using the CPU for 516ms burst [Q I A Q Y H Z S R U V B C T G N F P D K M L]
time 11327ms: Process W completed I/O; added to ready queue [Q I A Q Y H Z S R U V B C T G N F P D K M L W]
time 11783ms: Process O completed a CPU burst; 51 bursts to go [Q I A Q Y H Z S R U V B C T G N F P D K M L W]
time 11783ms: Process O switching out of CPU; will block on I/O until time 11833ms [Q I A Q Y H Z S R U V B C T G N F P D K M L W]
time 11789ms: Process I started using the CPU for 37ms burst [Q A Q Y H Z S R U V B C T G N F P D K M L W]
time 11826ms: Process I completed a CPU burst; 54 bursts to go [Q A Q Y H Z S R U V B C T G N F P D K M L W]
time 11826ms: Process I switching out of CPU; will block on I/O until time 11910ms [Q A Q Y H Z S R U V B C T G N F P D K M L W]
time 11832ms: Process A started using the CPU for 81ms burst [Q Q Y H Z S R U V B C T G N F P D K M L W]
time 11833ms: Process O completed I/O; added to ready queue [Q Q Y H Z S R U V B C T G N F P D K M L W O]
time 11910ms: Process I completed I/O; added to ready queue [Q Q Y H Z S R U V B C T G N F P D K M L W O I]
time 11913ms: Process A completed a CPU burst; 70 bursts to go [Q Q Y H Z S R U V B C T G N F P D K M L W O I]
time 11913ms: Process A switching out of CPU; will block on I/O until time 12020ms [Q Q Y H Z S R U V B C T G N F P D K M L W O I]
time 11919ms: Process Q started using the CPU for 5ms burst [Q Y H Z S R U V B C T G N F P D K M L W O I]
time 11924ms: Process Q completed a CPU burst; 86 bursts to go [Q Y H Z S R U V B C T G N F P D K M L W O I]
time 11924ms: Process Q switching out of CPU; will block on I/O until time 11955ms [Q Y H Z S R U V B C T G N F P D K M L W O I]
time 11930ms: Process Y started using the CPU for 14ms burst [Q H Z S R U V B C T G N F P D K M L W O I]
time 11944ms: Process Y completed a CPU burst; 25 bursts to go [Q H Z S R U V B C T G N F P D K M L W O I]
time 11944ms: Process Y switching out of CPU; will block on I/O until time 12090ms [Q H Z S R U V B C T G N F P D K M L W O I]
time 11950ms: Process H started using the CPU for 20ms burst [Q Z S R U V B C T G N F P D K M L W O I]
time 11955ms: Process Q completed I/O; added to ready queue [Q Z S R U V B C T G N F P D K M L W O I Q]
time 11970ms: Process H completed a CPU burst; 49 bursts to go [Q Z S R U V B C T G N F P D K M L W O I Q]
time 11970ms: Process H switching out of CPU; will block on I/O until time 12035ms [Q Z S R U V B C T G N F P D K M L W O I Q]
time 11976ms: Process Z started using the CPU for 85ms burst [Q S R U V B C T G N F P D K M L W O I Q]
time 12020ms: Process A completed I/O; added to ready queue [Q S R U V B C T G N F P D K M L W O I Q A]
time 12035ms: Process H completed I/O; added to ready queue [Q S R U V B C T G N F P D K M L W O I Q A H]
time 12061ms: Process Z completed a CPU burst; 79 bursts to go [Q S R U V B C T G N F P D K M L W O I Q A H]
time 12061ms: Process Z switching out of CPU; will block on I/O until time 12277ms [Q S R U V B C T G N F P D K M L W O I Q A H]
time 12067ms: Process S started using the CPU for 33ms burst [Q R U V B C T G N F P D K M L W O I Q A H]
time 12090ms: Process Y completed I/O; added to ready queue [Q R U V B C T G N F P D K M L W O I Q A H Y]
time 12100ms: Process S completed a CPU burst; 27 bursts to go [Q R U V B C T G N F P D K M L W O I Q A H Y]
time 12100ms: Process S switching out of CPU; will block on I/O until time 12111ms [Q R U V B C T G N F P D K M L W O I Q A H Y]
time 12106ms: Process R started using the CPU for 93ms burst [Q U V B C T G N F P D K M L W O I Q A H Y]
time 12111ms: Process S completed I/O; added to ready queue [Q U V B C T G N F P D K M L W O I Q A H Y S]
time 12199ms: Process R completed a CPU burst; 44 bursts to go [Q U V B C T G N F P D K M L W O I Q A H Y S]
time 12199ms: Process R switching out of CPU; will block on I/O until time 12360ms [Q U V B C T G N F P D K M L W O I Q A H Y S]
time 12205ms: Process U started using the CPU for 36ms burst [Q V B C T G N F P D K M L W O I Q A H Y S]
time 12241ms: Process U completed a CPU burst; 47 bursts to go [Q V B C T G N F P D K M L W O I Q A H Y S]
time 12241ms: Process U switching out of CPU; will block on I/O until time 12342ms [Q V B C T G N F P D K M L W O I Q A H Y S]
time 12247ms: Process V started using the CPU for 192ms burst [Q B C T G N F P D K M L W O I Q A H Y S]
time 12277ms: Process Z completed I/O; added to ready queue [Q B C T G N F P D K M L W O I Q A H Y S Z]
time 12342ms: Process U completed I/O; added to ready queue [Q B C T G N F P D K M L W O I Q A H Y S Z U]
time 12360ms: Process R completed I/O; added to ready queue [Q B C T G N F P D K M L W O I Q A H Y S Z U R]
time 12439ms: Process V completed a CPU burst; 26 bursts to go [Q B C T G N F P D K M L W O I Q A H Y S Z U R]
time 12439ms: Process V switching out of CPU; will block on I/O until time 12521ms [Q B C T G N F P D K M L W O I Q A H Y S Z U R]
time 12445ms: Process B started using the CPU for 77ms burst [Q C T G N F P D K M L W O I Q A H Y S Z U R]
time 12521ms: Process V completed I/O; added to ready queue [Q C T G N F P D K M L W O I Q A H Y S Z U R V]
time 12522ms: Process B completed a CPU burst; 79 bursts to go [Q C T G N F P D K M L W O I Q A H Y S Z U R V]
time 12522ms: Process B switching out of CPU; will block on I/O until time 12665ms [Q C T G N F P D K M L W O I Q A H Y S Z U R V]
time 12528ms: Process C started using the CPU for 46ms burst [Q T G N F P D K M L W O I Q A H Y S Z U R V]
time 12574ms: Process C completed a CPU burst; 52 bursts to go [Q T G N F P D K M L W O I Q A H Y S Z U R V]
time 12574ms: Process C switching out of CPU; will block on I/O until time 12845ms [Q T G N F P D K M L W O I Q A H Y S Z U R V]
time 12580ms: Process T started using the CPU for 36ms burst [Q G N F P D K M L W O I Q A H Y S Z U R V]
time 12616ms: Process T completed a CPU burst; 46 bursts to go [Q G N F P D K M L W O I Q A H Y S Z U R V]
time 12616ms: Process T switching out of CPU; will block on I/O until time 13004ms [Q G N F P D K M L W O I Q A H Y S Z U R V]
time 12622ms: Process G started using the CPU for 59ms burst [Q N F P D K M L W O I Q A H Y S Z U R V]
time 12665ms: Process B completed I/O; added to ready queue [Q N F P D K M L W O I Q A H Y S Z U R V B]
time 12681ms: Process G completed a CPU burst; 73 bursts to go [Q N F P D K M L W O I Q A H Y S Z U R V B]
time 12681ms: Process G switching out of CPU; will block on I/O until time 13100ms [Q N F P D K M L W O I Q A H Y S Z U R V B]
time 12687ms: Process N started using the CPU for 38ms burst [Q F P D K M L W O I Q A H Y S Z U R V B]
time 12725ms: Process N completed a CPU burst; 52 bursts to go [Q F P D K M L W O I Q A H Y S Z U R V B]
time 12725ms: Process N switching out of CPU; will block on I/O until time 12825ms [Q F P D K M L W O I Q A H Y S Z U R V B]
time 12731ms: Process F started using the CPU for 217ms burst [Q P D K M L W O I Q A H Y S Z U R V B]
time 12825ms: Process N completed I/O; added to ready queue [Q P D K M L W O I Q A H Y S Z U R V B N]
time 12845ms: Process C completed I/O; added to ready queue [Q P D K M L W O I Q A H Y S Z U R V B N C]
time 12948ms: Process F completed a CPU burst; 8 bursts to go [Q P D K M L W O I Q A H Y S Z U R V B N C]
time 12948ms: Process F switching out of CPU; will block on I/O until time 13028ms [Q P D K M L W O I Q A H Y S Z U R V B N C]
time 12954ms: Process P started using the CPU for 130ms burst [Q D K M L W O I Q A H Y S Z U R V B N C]
time 13004ms: Process T completed I/O; added to ready queue [Q D K M L W O I Q A H Y S Z U R V B N C T]
time 13028ms: Process F completed I/O; added to ready queue [Q D K M L W O I Q A H Y S Z U R V B N C T F]
time 13084ms: Process P completed a CPU burst; 79 bursts to go [Q D K M L W O I Q A H Y S Z U R V B N C T F]
time 13084ms: Process P switching out of CPU; will block on I/O until time 13111ms [Q D K M L W O I Q A H Y S Z U R V B N C T F]
time 13090ms: Process D started using the CPU for 52ms burst [Q K M L W O I Q A H Y S Z U R V B N C T F]
time 13100ms: Process G completed I/O; added to ready queue [Q K M L W O I Q A H Y S Z U R V B N C T F G]
time 13111ms: Process P completed I/O; added to ready queue [Q K M L W O I Q A H Y S Z U R V B N C T F G P]
time 13142ms: Process D completed a CPU burst; 62 bursts to go [Q K M L W O I Q A H Y S Z U R V B N C T F G P]
time 13142ms: Process D switching out of CPU; will block on I/O until time 13431ms [Q K M L W O I Q A H Y S Z U R V B N C T F G P]
time 13148ms: Process K started using the CPU for 189ms burst [Q M L W O I Q A H Y S Z U R V B N C T F G P]
time 13337ms: Process K completed a CPU burst; 82 bursts to go [Q M L W O I Q A H Y S Z U R V B N C T F G P]
time 13337ms: Process K switching out of CPU; will block on I/O until time 13640ms [Q M L W O I Q A H Y S Z U R V B N C T F G P]
time 13343ms: Process M started using the CPU for 17ms burst [Q L W O I Q A H Y S Z U R V B N C T F G P]
time 13360ms: Process M completed a CPU burst; 32 bursts to go [Q L W O I Q A H Y S Z U R V B N C T F G P]
time 13360ms: Process M switching out of CPU; will block on I/O until time 13481ms [Q L W O I Q A H Y S Z U R V B N C T F G P]
time 13366ms: Process L started using the CPU for 67ms burst [Q W O I Q A H Y S Z U R V B N C T F G P]
time 13431ms: Process D completed I/O; added to ready queue [Q W O I Q A H Y S Z U R V B N C T F G P D]
time 13433ms: Process L completed a CPU burst; 19 bursts to go [Q W O I Q A H Y S Z U R V B N C T F G P D]
time 13433ms: Process L switching out of CPU; will block on I/O until time 13511ms [Q W O I Q A H Y S Z U R V B N C T F G P D]
time 13439ms: Process W started using the CPU for 84ms burst [Q O I Q A H Y S Z U R V B N C T F G P D]
time 13481ms: Process M completed I/O; added to ready queue [Q O I Q A H Y S Z U R V B N C T F G P D M]
time 13511ms: Process L completed I/O; added to ready queue [Q O I Q A H Y S Z U R V B N C T F G P D M L]
time 13523ms: Process W completed a CPU burst; 17 bursts to go [Q O I Q A H Y S Z U R V B N C T F G P D M L]
time 13523ms: Process W switching out of CPU; will block on I/O until time 13573ms [Q O I Q A H Y S Z U R V B N C T F G P D M L]
time 13529ms: Process O started using the CPU for 166ms burst [Q I Q A H Y S Z U R V B N C T F G P D M L]
time 13573ms: Process W completed I/O; added to ready queue [Q I Q A H Y S Z U R V B N C T F G P D M L W]
time 13640ms: Process K completed I/O; added to ready queue [Q I Q A H Y S Z U R V B N C T F G P D M L W K]
time 13695ms: Process O completed a CPU burst; 50 bursts to go [Q I Q A H Y S Z U R V B N C T F G P D M L W K]
time 13695ms: Process O switching out of CPU; will block on I/O until time 13751ms [Q I Q A H Y S Z U R V B N C T F G P D M L W K]
time 13701ms: Process I started using the CPU for 136ms burst [Q Q A H Y S Z U R V B N C T F G P D M L W K]
time 13751ms: Process O completed I/O; added to ready queue [Q Q A H Y S Z U R V B N C T F G P D M L W K O]
time 13837ms: Process I completed a CPU burst; 53 bursts to go [Q Q A H Y S Z U R V B N C T F G P D M L W K O]
time 13837ms: Process I switching out of CPU; will block on I/O until time 14005ms [Q Q A H Y S Z U R V B N C T F G P D M L W K O]
time 13843ms: Process Q started using the CPU for 263ms burst [Q A H Y S Z U R V B N C T F G P D M L W K O]
time 14005ms: Process I completed I/O; added to ready queue [Q A H Y S Z U R V B N C T F G P D M L W K O I]
time 14106ms: Process Q completed a CPU burst; 85 bursts to go [Q A H Y S Z U R V B N C T F G P D M L W K O I]
time 14106ms: Process Q switching out of CPU; will block on I/O until time 14261ms [Q A H Y S Z U R V B N C T F G P D M L W K O I]
time 14112ms: Process A started using the CPU for 32ms burst [Q H Y S Z U R V B N C T F G P D M L W K O I]
time 14144ms: Process A completed a CPU burst; 69 bursts to go [Q H Y S Z U R V B N C T F G P D M L W K O I]
time 14144ms: Process A switching out of CPU; will block on I/O until time 14282ms [Q H Y S Z U R V B N C T F G P D M L W K O I]
time 14150ms: Process H started using the CPU for 26ms burst [Q Y S Z U R V B N C T F G P D M L W K O I]
time 14176ms: Process H completed a CPU burst; 48 bursts to go [Q Y S Z U R V B N C T F G P D M L W K O I]
time 14176ms: Process H switching out of CPU; will block on I/O until time 14511ms [Q Y S Z U R V B N C T F G P D M L W K O I]
time 14182ms: Process Y started using the CPU for 188ms burst [Q S Z U R V B N C T F G P D M L W K O I]
time 14261ms: Process Q completed I/O; added to ready queue [Q S Z U R V B N C T F G P D M L W K O I Q]
time 14282ms: Process A completed I/O; added to ready queue [Q S Z U R V B N C T F G P D M L W K O I Q A]
time 14370ms: Process Y completed a CPU burst; 24 bursts to go [Q S Z U R V B N C T F G P D M L W K O I Q A]
time 14370ms: Process Y switching out of CPU; will block on I/O until time 14472ms [Q S Z U R V B N C T F G P D M L W K O I Q A]
time 14376ms: Process S started using the CPU for 130ms burst [Q Z U R V B N C T F G P D M L W K O I Q A]
time 14472ms: Process Y completed I/O; added to ready queue [Q Z U R V B N C T F G P D M L W K O I Q A Y]
time 14506ms: Process S completed a CPU burst; 26 bursts to go [Q Z U R V B N C T F G P D M L W K O I Q A Y]
time 14506ms: Process S switching out of CPU; will block on I/O until time 14539ms [Q Z U R V B N C T F G P D M L W K O I Q A Y]
time 14511ms: Process H completed I/O; added to ready queue [Q U R V B N C T F G P D M L W K O I Q A Y H]
time 14512ms: Process Z started using the CPU for 86ms burst [Q U R V B N C T F G P D M L W K O I Q A Y H]
time 14539ms: Process S completed I/O; added to ready queue [Q U R V B N C T F G P D M L W K O I Q A Y H S]
time 14598ms: Process Z completed a CPU burst; 78 bursts to go [Q U R V B N C T F G P D M L W K O I Q A Y H S]
time 14598ms: Process Z switching out of CPU; will block on I/O until time 14644ms [Q U R V B N C T F G P D M L W K O I Q A Y H S]
time 14604ms: Process U started using the CPU for 126ms burst [Q R V B N C T F G P D M L W K O I Q A Y H S]
time 14644ms: Process Z completed I/O; added to ready queue [Q R V B N C T F G P D M L W K O I Q A Y H S Z]
time 14730ms: Process U completed a CPU burst; 46 bursts to go [Q R V B N C T F G P D M L W K O I Q A Y H S Z]
time 14730ms: Process U switching out of CPU; will block on I/O until time 14796ms [Q R V B N C T F G P D M L W K O I Q A Y H S Z]
time 14736ms: Process R started using the CPU for 61ms burst [Q V B N C T F G P D M L W K O I Q A Y H S Z]
time 14796ms: Process U completed I/O; added to ready queue [Q V B N C T F G P D M L W K O I Q A Y H S Z U]
time 14797ms: Process R completed a CPU burst; 43 bursts to go [Q V B N C T F G P D M L W K O I Q A Y H S Z U]
time 14797ms: Process R switching out of CPU; will block on I/O until time 14803ms [Q V B N C T F G P D M L W K O I Q A Y H S Z U]
time 14803ms: Process V started using the CPU for 284ms burst [Q B N C T F G P D M L W K O I Q A Y H S Z U]
time 14803ms: Process R completed I/O; added to ready queue [Q B N C T F G P D M L W K O I Q A Y H S Z U R]
time 15087ms: Process V completed a CPU burst; 25 bursts to go [Q B N C T F G P D M L W K O I Q A Y H S Z U R]
time 15087ms: Process V switching out of CPU; will block on I/O until time 15104ms [Q B N C T F G P D M L W K O I Q A Y H S Z U R]
time 15093ms: Process B started using the CPU for 17ms burst [Q N C T F G P D M L W K O I Q A Y H S Z U R]
time 15104ms: Process V completed I/O; added to ready queue [Q N C T F G P D M L W K O I Q A Y H S Z U R V]
time 15110ms: Process B completed a CPU burst; 78 bursts to go [Q N C T F G P D M L W K O I Q A Y H S Z U R V]
time 15110ms: Process B switching out of CPU; will block on I/O until time 15131ms [Q N C T F G P D M L W K O I Q A Y H S Z U R V]
time 15116ms: Process N started using the CPU for 338ms burst [Q C T F G P D M L W K O I Q A Y H S Z U R V]
time 15131ms: Process B completed I/O; added to ready queue [Q C T F G P D M L W K O I Q A Y H S Z U R V B]
time 15454ms: Process N completed a CPU burst; 51 bursts to go [Q C T F G P D M L W K O I Q A Y H S Z U R V B]
time 15454ms: Process N switching out of CPU; will block on I/O until time 15639ms [Q C T F G P D M L W K O I Q A Y H S Z U R V B]
time 15460ms: Process C started using the CPU for 204ms burst [Q T F G P D M L W K O I Q A Y H S Z U R V B]
time 15639ms: Process N completed I/O; added to ready queue [Q T F G P D M L W K O I Q A Y H S Z U R V B N]
time 15664ms: Process C completed a CPU burst; 51 bursts to go [Q T F G P D M L W K O I Q A Y H S Z U R V B N]
time 15664ms: Process C switching out of CPU; will block on I/O until time 15695ms [Q T F G P D M L W K O I Q A Y H S Z U R V B N]
time 15670ms: Process T started using the CPU for 13ms burst [Q F G P D M L W K O I Q A Y H S Z U R V B N]
time 15683ms: Process T completed a CPU burst; 45 bursts to go [Q F G P D M L W K O I Q A Y H S Z U R V B N]
time 15683ms: Process T switching out of CPU; will block on I/O until time 15688ms [Q F G P D M L W K O I Q A Y H S Z U R V B N]
time 15688ms: Process T completed I/O; added to ready queue [Q G P D M L W K O I Q A Y H S Z U R V B N T]
time 15689ms: Process F started using the CPU for 94ms burst [Q G P D M L W K O I Q A Y H S Z U R V B N T]
time 15695ms: Process C completed I/O; added to ready queue [Q G P D M L W K O I Q A Y H S Z U R V B N T C]
time 15783ms: Process F completed a CPU burst; 7 bursts to go [Q G P D M L W K O I Q A Y H S Z U R V B N T C]
time 15783ms: Process F switching out of CPU; will block on I/O until time 15883ms [Q G P D M L W K O I Q A Y H S Z U R V B N T C]
time 15789ms: Process G started using the CPU for 79ms burst [Q P D M L W K O I Q A Y H S Z U R V B N T C]
time 15868ms: Process G completed a CPU burst; 72 bursts to go [Q P D M L W K O I Q A Y H S Z U R V B N T C]
time 15868ms: Process G switching out of CPU; will block on I/O until time 15941ms [Q P D M L W K O I Q A Y H S Z U R V B N T C]
time 15874ms: Process P started using the CPU for 4ms burst [Q D M L W K O I Q A Y H S Z U R V B N T C]
time 15878ms: Process P completed a CPU burst; 78 bursts to go [Q D M L W K O I Q A Y H S Z U R V B N T C]
time 15878ms: Process P switching out of CPU; will block on I/O until time 16054ms [Q D M L W K O I Q A Y H S Z U R V B N T C]
time 15883ms: Process F completed I/O; added to ready queue [Q M L W K O I Q A Y H S Z U R V B N T C F]
time 15884ms: Process D started using the CPU for 211ms burst [Q M L W K O I Q A Y H S Z U R V B N T C F]
time 15941ms: Process G completed I/O; added to ready queue [Q M L W K O I Q A Y H S Z U R V B N T C F G]
time 16054ms: Process P completed I/O; added to ready queue [Q M L W K O I Q A Y H S Z U R V B N T C F G P]
time 16095ms: Process D completed a CPU burst; 61 bursts to go [Q M L W K O I Q A Y H S Z U R V B N T C F G P]
time 16095ms: Process D switching out of CPU; will block on I/O until time 16156ms [Q M L W K O I Q A Y H S Z U R V B N T C F G P]
time 16101ms: Process M started using the CPU for 36ms burst [Q L W K O I Q A Y H S Z U R V B N T C F G P]
time 16137ms: Process M completed a CPU burst; 31 bursts to go [Q L W K O I Q A Y H S Z U R V B N T C F G P]
time 16137ms: Process M switching out of CPU; will block on I/O until time 16141ms [Q L W K O I Q A Y H S Z U R V B N T C F G P]
time 16141ms: Process M completed I/O; added to ready queue [Q W K O I Q A Y H S Z U R V B N T C F G P M]
time 16143ms: Process L started using the CPU for 98ms burst [Q W K O I Q A Y H S Z U R V B N T C F G P M]
time 16156ms: Process D completed I/O; added to ready queue [Q W K O I Q A Y H S Z U R V B N T C F G P M D]
time 16241ms: Process L completed a CPU burst; 18 bursts to go [Q W K O I Q A Y H S Z U R V B N T C F G P M D]
time 16241ms: Process L switching out of CPU; will block on I/O until time 16422ms [Q W K O I Q A Y H S Z U R V B N T C F G P M D]
time 16247ms: Process W started using the CPU for 32ms burst [Q K O I Q A Y H S Z U R V B N T C F G P M D]
time 16279ms: Process W completed a CPU burst; 16 bursts to go [Q K O I Q A Y H S Z U R V B N T C F G P M D]
time 16279ms: Process W switching out of CPU; will block on I/O until time 16306ms [Q K O I Q A Y H S Z U R V B N T C F G P M D]
time 16285ms: Process K started using the CPU for 192ms burst [Q O I Q A Y H S Z U R V B N T C F G P M D]
time 16306ms: Process W completed I/O; added to ready queue [Q O I Q A Y H S Z U R V B N T C F G P M D W]
time 16422ms: Process L completed I/O; added to ready queue [Q O I Q A Y H S Z U R V B N T C F G P M D W L]
time 16477ms: Process K completed a CPU burst; 81 bursts to go [Q O I Q A Y H S Z U R V B N T C F G P M D W L]
time 16477ms: Process K switching out of CPU; will block on I/O until time 16481ms [Q O I Q A Y H S Z U R V B N T C F G P M D W L]
time 16481ms: Process K completed I/O; added to ready queue [Q I Q A Y H S Z U R V B N T C F G P M D W L K]
time 16483ms: Process O started using the CPU for 173ms burst [Q I Q A Y H S Z U R V B N T C F G P M D W L K]
time 16656ms: Process O completed a CPU burst; 49 bursts to go [Q I Q A Y H S Z U R V B N T C F G P M D W L K]
time 16656ms: Process O switching out of CPU; will block on I/O until time 16710ms [Q I Q A Y H S Z U R V B N T C F G P M D W L K]
time 16662ms: Process I started using the CPU for 108ms burst [Q Q A Y H S Z U R V B N T C F G P M D W L K]
time 16710ms: Process O completed I/O; added to ready queue [Q Q A Y H S Z U R V B N T C F G P M D W L K O]
time 16770ms: Process I completed a CPU burst; 52 bursts to go [Q Q A Y H S Z U R V B N T C F G P M D W L K O]
time 16770ms: Process I switching out of CPU; will block on I/O until time 16804ms [Q Q A Y H S Z U R V B N T C F G P M D W L K O]
time 16776ms: Process Q started using the CPU for 43ms burst [Q A Y H S Z U R V B N T C F G P M D W L K O]
time 16804ms: Process I completed I/O; added to ready queue [Q A Y H S Z U R V B N T C F G P M D W L K O I]
time 16819ms: Process Q completed a CPU burst; 84 bursts to go [Q A Y H S Z U R V B N T C F G P M D W L K O I]
time 16819ms: Process Q switching out of CPU; will block on I/O until time 16946ms [Q A Y H S Z U R V B N T C F G P M D W L K O I]
time 16825ms: Process A started using the CPU for 94ms burst [Q Y H S Z U R V B N T C F G P M D W L K O I]
time 16919ms: Process A completed a CPU burst; 68 bursts to go [Q Y H S Z U R V B N T C F G P M D W L K O I]
time 16919ms: Process A switching out of CPU; will block on I/O until time 16948ms [Q Y H S Z U R V B N T C F G P M D W L K O I]
time 16925ms: Process Y started using the CPU for 243ms burst [Q H S Z U R V B N T C F G P M D W L K O I]
time 16946ms: Process Q completed I/O; added to ready queue [Q H S Z U R V B N T C F G P M D W L K O I Q]
time 16948ms: Process A completed I/O; added to ready queue [Q H S Z U R V B N T C F G P M D W L K O I Q A]
time 17168ms: Process Y completed a CPU burst; 23 bursts to go [Q H S Z U R V B N T C F G P M D W L K O I Q A]
time 17168ms: Process Y switching out of CPU; will block on I/O until time 17187ms [Q H S Z U R V B N T C F G P M D W L K O I Q A]
time 17174ms: Process H started using the CPU for 7ms burst [Q S Z U R V B N T C F G P M D W L K O I Q A]
time 17181ms: Process H completed a CPU burst; 47 bursts to go [Q S Z U R V B N T C F G P M D W L K O I Q A]
time 17181ms: Process H switching out of CPU; will block on I/O until time 17209ms [Q S Z U R V B N T C F G P M D W L K O I Q A]
time 17187ms: Process S started using the CPU for 29ms burst [Q Z U R V B N T C F G P M D W L K O I Q A]
time 17187ms: Process Y completed I/O; added to ready queue [Q Z U R V B N T C F G P M D W L K O I Q A Y]
time 17209ms: Process H completed I/O; added to ready queue [Q Z U R V B N T C F G P M D W L K O I Q A Y H]
time 17216ms: Process S completed a CPU burst; 25 bursts to go [Q Z U R V B N T C F G P M D W L K O I Q A Y H]
time 17216ms: Process S switching out of CPU; will block on I/O until time 17232ms [Q Z U R V B N T C F G P M D W L K O I Q A Y H]
time 17222ms: Process Z started using the CPU for 163ms burst [Q U R V B N T C F G P M D W L K O I Q A Y H]
time 17232ms: Process S completed I/O; added to ready queue [Q U R V B N T C F G P M D W L K O I Q A Y H S]
time 17385ms: Process Z completed a CPU burst; 77 bursts to go [Q U R V B N T C F G P M D W L K O I Q A Y H S]
time 17385ms: Process Z switching out of CPU; will block on I/O until time 17611ms [Q U R V B N T C F G P M D W L K O I Q A Y H S]
time 17391ms: Process U started using the CPU for 61ms burst [Q R V B N T C F G P M D W L K O I Q A Y H S]
time 17452ms: Process U completed a CPU burst; 45 bursts to go [Q R V B N T C F G P M D W L K O I Q A Y H S]
time 17452ms: Process U switching out of CPU; will block on I/O until time 17634ms [Q R V B N T C F G P M D W L K O I Q A Y H S]
time 17458ms: Process R started using the CPU for 301ms burst [Q V B N T C F G P M D W L K O I Q A Y H S]
time 17611ms: Process Z completed I/O; added to ready queue [Q V B N T C F G P M D W L K O I Q A Y H S Z]
time 17634ms: Process U completed I/O; added to ready queue [Q V B N T C F G P M D W L K O I Q A Y H S Z U]
time 17759ms: Process R completed a CPU burst; 42 bursts to go [Q V B N T C F G P M D W L K O I Q A Y H S Z U]
time 17759ms: Process R switching out of CPU; will block on I/O until time 17831ms [Q V B N T C F G P M D W L K O I Q A Y H S Z U]
time 17765ms: Process V started using the CPU for 176ms burst [Q B N T C F G P M D W L K O I Q A Y H S Z U]
time 17831ms: Process R completed I/O; added to ready queue [Q B N T C F G P M D W L K O I Q A Y H S Z U R]
time 17941ms: Process V completed a CPU burst; 24 bursts to go [Q B N T C F G P M D W L K O I Q A Y H S Z U R]
time 17941ms: Process V switching out of CPU; will block on I/O until time 18021ms [Q B N T C F G P M D W L K O I Q A Y H S Z U R]
time 17947ms: Process B started using the CPU for 31ms burst [Q N T C F G P M D W L K O I Q A Y H S Z U R]
time 17978ms: Process B completed a CPU burst; 77 bursts to go [Q N T C F G P M D W L K O I Q A Y H S Z U R]
time 17978ms: Process B switching out of CPU; will block on I/O until time 18184ms [Q N T C F G P M D W L K O I Q A Y H S Z U R]
time 17984ms: Process N started using the CPU for 50ms burst [Q T C F G P M D W L K O I Q A Y H S Z U R]
time 18021ms: Process V completed I/O; added to ready queue [Q T C F G P M D W L K O I Q A Y H S Z U R V]
time 18034ms: Process N completed a CPU burst; 50 bursts to go [Q T C F G P M D W L K O I Q A Y H S Z U R V]
time 18034ms: Process N switching out of CPU; will block on I/O until time 18187ms [Q T C F G P M D W L K O I Q A Y H S Z U R V]
time 18040ms: Process T started using the CPU for 73ms burst [Q C F G P M D W L K O I Q A Y H S Z U R V]
time 18113ms: Process T completed a CPU burst; 44 bursts to go [Q C F G P M D W L K O I Q A Y H S Z U R V]
time 18113ms: Process T switching out of CPU; will block on I/O until time 18160ms [Q C F G P M D W L K O I Q A Y H S Z U R V]
time 18119ms: Process C started using the CPU for 74ms burst [Q F G P M D W L K O I Q A Y H S Z U R V]
time 18160ms: Process T completed I/O; added to ready queue [Q F G P M D W L K O I Q A Y H S Z U R V T]
time 18184ms: Process B completed I/O; added to ready queue [Q F G P M D W L K O I Q A Y H S Z U R V T B]
time 18187ms: Process N completed I/O; added to ready queue [Q F G P M D W L K O I Q A Y H S Z U R V T B N]
time 18193ms: Process C completed a CPU burst; 50 bursts to go [Q F G P M D W L K O I Q A Y H S Z U R V T B N]
time 18193ms: Process C switching out of CPU; will block on I/O until time 18230ms [Q F G P M D W L K O I Q A Y H S Z U R V T B N]
time 18199ms: Process F started using the CPU for 138ms burst [Q G P M D W L K O I Q A Y H S Z U R V T B N]
time 18230ms: Process C completed I/O; added to ready queue [Q G P M D W L K O I Q A Y H S Z U R V T B N C]
time 18337ms: Process F completed a CPU burst; 6 bursts to go [Q G P M D W L K O I Q A Y H S Z U R V T B N C]
time 18337ms: Process F switching out of CPU; will block on I/O until time 18542ms [Q G P M D W L K O I Q A Y H S Z U R V T B N C]
time 18343ms: Process G started using the CPU for 139ms burst [Q P M D W L K O I Q A Y H S Z U R V T B N C]
time 18482ms: Process G completed a CPU burst; 71 bursts to go [Q P M D W L K O I Q A Y H S Z U R V T B N C]
time 18482ms: Process G switching out of CPU; will block on I/O until time 18553ms [Q P M D W L K O I Q A Y H S Z U R V T B N C]
time 18488ms: Process P started using the CPU for 97ms burst [Q M D W L K O I Q A Y H S Z U R V T B N C]
time 18542ms: Process F completed I/O; added to ready queue [Q M D W L K O I Q A Y H S Z U R V T B N C F]
time 18553ms: Process G completed I/O; added to ready queue [Q M D W L K O I Q A Y H S Z U R V T B N C F G]
time 18585ms: Process P completed a CPU burst; 77 bursts to go [Q M D W L K O I Q A Y H S Z U R V T B N C F G]
time 18585ms: Process P switching out of CPU; will block on I/O until time 18677ms [Q M D W L K O I Q A Y H S Z U R V T B N C F G]
time 18591ms: Process M started using the CPU for 83ms burst [Q D W L K O I Q A Y H S Z U R V T B N C F G]
time 18674ms: Process M completed a CPU burst; 30 bursts to go [Q D W L K O I Q A Y H S Z U R V T B N C F G]
time 18674ms: Process M switching out of CPU; will block on I/O until time 18751ms [Q D W L K O I Q A Y H S Z U R V T B N C F G]
time 18677ms: Process P completed I/O; added to ready queue [Q D W L K O I Q A Y H S Z U R V T B N C F G P]
time 18680ms: Process D started using the CPU for 43ms burst [Q W L K O I Q A Y H S Z U R V T B N C F G P]
time 18723ms: Process D completed a CPU burst; 60 bursts to go [Q W L K O I Q A Y H S Z U R V T B N C F G P]
time 18723ms: Process D switching out of CPU; will block on I/O until time 19002ms [Q W L K O I Q A Y H S Z U R V T B N C F G P]
time 18729ms: Process W started using the CPU for 30ms burst [Q L K O I Q A Y H S Z U R V T B N C F G P]
time 18751ms: Process M completed I/O; added to ready queue [Q L K O I Q A Y H S Z U R V T B N C F G P M]
time 18759ms: Process W completed a CPU burst; 15 bursts to go [Q L K O I Q A Y H S Z U R V T B N C F G P M]
time 18759ms: Process W switching out of CPU; will block on I/O until time 18798ms [Q L K O I Q A Y H S Z U R V T B N C F G P M]
time 18765ms: Process L started using the CPU for 73ms burst [Q K O I Q A Y H S Z U R V T B N C F G P M]
time 18798ms: Process W completed I/O; added to ready queue [Q K O I Q A Y H S Z U R V T B N C F G P M W]
time 18838ms: Process L completed a CPU burst; 17 bursts to go [Q K O I Q A Y H S Z U R V T B N C F G P M W]
time 18838ms: Process L switching out of CPU; will block on I/O until time 19073ms [Q K O I Q A Y H S Z U R V T B N C F G P M W]
time 18844ms: Process K started using the CPU for 158ms burst [Q O I Q A Y H S Z U R V T B N C F G P M W]
time 19002ms: Process K completed a CPU burst; 80 bursts to go [Q O I Q A Y H S Z U R V T B N C F G P M W]
time 19002ms: Process K switching out of CPU; will block on I/O until time 19040ms [Q O I Q A Y H S Z U R V T B N C F G P M W]
time 19002ms: Process D completed I/O; added to ready queue [Q O I Q A Y H S Z U R V T B N C F G P M W D]
time 19008ms: Process O started using the CPU for 106ms burst [Q I Q A Y H S Z U R V T B N C F G P M W D]
time 19040ms: Process K completed I/O; added to ready queue [Q I Q A Y H S Z U R V T B N C F G P M W D K]
time 19073ms: Process L completed I/O; added to ready queue [Q I Q A Y H S Z U R V T B N C F G P M W D K L]
time 19114ms: Process O completed a CPU burst; 48 bursts to go [Q I Q A Y H S Z U R V T B N C F G P M W D K L]
time 19114ms: Process O switching out of CPU; will block on I/O until time 19202ms [Q I Q A Y H S Z U R V T B N C F G P M W D K L]
time 19120ms: Process I started using the CPU for 106ms burst [Q Q A Y H S Z U R V T B N C F G P M W D K L]
time 19202ms: Process O completed I/O; added to ready queue [Q Q A Y H S Z U R V T B N C F G P M W D K L O]
time 19226ms: Process I completed a CPU burst; 51 bursts to go [Q Q A Y H S Z U R V T B N C F G P M W D K L O]
time 19226ms: Process I switching out of CPU; will block on I/O until time 19246ms [Q Q A Y H S Z U R V T B N C F G P M W D K L O]
time 19232ms: Process Q started using the CPU for 24ms burst [Q A Y H S Z U R V T B N C F G P M W D K L O]
time 19246ms: Process I completed I/O; added to ready queue [Q A Y H S Z U R V T B N C F G P M W D K L O I]
time 19256ms: Process Q completed a CPU burst; 83 bursts to go [Q A Y H S Z U R V T B N C F G P M W D K L O I]
time 19256ms: Process Q switching out of CPU; will block on I/O until time 19290ms [Q A Y H S Z U R V T B N C F G P M W D K L O I]
time 19262ms: Process A started using the CPU for 17ms burst [Q Y H S Z U R V T B N C F G P M W D K L O I]
time 19279ms: Process A completed a CPU burst; 67 bursts to go [Q Y H S Z U R V T B N C F G P M W D K L O I]
time 19279ms: Process A switching out of CPU; will block on I/O until time 19338ms [Q Y H S Z U R V T B N C F G P M W D K L O I]
time 19285ms: Process Y started using the CPU for 23ms burst [Q H S Z U R V T B N C F G P M W D K L O I]
time 19290ms: Process Q completed I/O; added to ready queue [Q H S Z U R V T B N C F G P M W D K L O I Q]
time 19308ms: Process Y completed a CPU burst; 22 bursts to go [Q H S Z U R V T B N C F G P M W D K L O I Q]
time 19308ms: Process Y switching out of CPU; will block on I/O until time 19319ms [Q H S Z U R V T B N C F G P M W D K L O I Q]
time 19314ms: Process H started using the CPU for 79ms burst [Q S Z U R V T B N C F G P M W D K L O I Q]
time 19319ms: Process Y completed I/O; added to ready queue [Q S Z U R V T B N C F G P M W D K L O I Q Y]
time 19338ms: Process A completed I/O; added to ready queue [Q S Z U R V T B N C F G P M W D K L O I Q Y A]
time 19393ms: Process H completed a CPU burst; 46 bursts to go [Q S Z U R V T B N C F G P M W D K L O I Q Y A]
time 19393ms: Process H switching out of CPU; will block on I/O until time 19404ms [Q S Z U R V T B N C F G P M W D K L O I Q Y A]
time 19399ms: Process S started using the CPU for 30ms burst [Q Z U R V T B N C F G P M W D K L O I Q Y A]
time 19404ms: Process H completed I/O; added to ready queue [Q Z U R V T B N C F G P M W D K L O I Q Y A H]
time 19429ms: Process S completed a CPU burst; 24 bursts to go [Q Z U R V T B N C F G P M W D K L O I Q Y A H]
time 19429ms: Process S switching out of CPU; will block on I/O until time 19435ms [Q Z U R V T B N C F G P M W D K L O I Q Y A H]
time 19435ms: Process Z started using the CPU for 107ms burst [Q U R V T B N C F G P M W D K L O I Q Y A H]
time 19435ms: Process S completed I/O; added to ready queue [Q U R V T B N C F G P M W D K L O I Q Y A H S]
time 19542ms: Process Z completed a CPU burst; 76 bursts to go [Q U R V T B N C F G P M W D K L O I Q Y A H S]
time 19542ms: Process Z switching out of CPU; will block on I/O until time 19747ms [Q U R V T B N C F G P M W D K L O I Q Y A H S]
time 19548ms: Process U started using the CPU for 86ms burst [Q R V T B N C F G P M W D K L O I Q Y A H S]
time 19634ms: Process U completed a CPU burst; 44 bursts to go [Q R V T B N C F G P M W D K L O I Q Y A H S]
time 19634ms: Process U switching out of CPU; will block on I/O until time 19688ms [Q R V T B N C F G P M W D K L O I Q Y A H S]
time 19640ms: Process R started using the CPU for 365ms burst [Q V T B N C F G P M W D K L O I Q Y A H S]
time 19688ms: Process U completed I/O; added to ready queue [Q V T B N C F G P M W D K L O I Q Y A H S U]
time 19747ms: Process Z completed I/O; added to ready queue [Q V T B N C F G P M W D K L O I Q Y A H S U Z]
time 20005ms: Process R completed a CPU burst; 41 bursts to go [Q V T B N C F G P M W D K L O I Q Y A H S U Z]
time 20005ms: Process R switching out of CPU; will block on I/O until time 20030ms [Q V T B N C F G P M W D K L O I Q Y A H S U Z]
time 20011ms: Process V started using the CPU for 21ms burst [Q T B N C F G P M W D K L O I Q Y A H S U Z]
time 20030ms: Process R completed I/O; added to ready queue [Q T B N C F G P M W D K L O I Q Y A H S U Z R]
time 20032ms: Process V completed a CPU burst; 23 bursts to go [Q T B N C F G P M W D K L O I Q Y A H S U Z R]
time 20032ms: Process V switching out of CPU; will block on I/O until time 20089ms [Q T B N C F G P M W D K L O I Q Y A H S U Z R]
time 20038ms: Process T started using the CPU for 90ms burst [Q B N C F G P M W D K L O I Q Y A H S U Z R]
time 20089ms: Process V completed I/O; added to ready queue [Q B N C F G P M W D K L O I Q Y A H S U Z R V]
time 20128ms: Process T completed a CPU burst; 43 bursts to go [Q B N C F G P M W D K L O I Q Y A H S U Z R V]
time 20128ms: Process T switching out of CPU; will block on I/O until time 20144ms [Q B N C F G P M W D K L O I Q Y A H S U Z R V]
time 20134ms: Process B started using the CPU for 75ms burst [Q N C F G P M W D K L O I Q Y A H S U Z R V]
time 20144ms: Process T completed I/O; added to ready queue [Q N C F G P M W D K L O I Q Y A H S U Z R V T]
time 20209ms: Process B completed a CPU burst; 76 bursts to go [Q N C F G P M W D K L O I Q Y A H S U Z R V T]
time 20209ms: Process B switching out of CPU; will block on I/O until time 20237ms [Q N C F G P M W D K L O I Q Y A H S U Z R V T]
time 20215ms: Process N started using the CPU for 329ms burst [Q C F G P M W D K L O I Q Y A H S U Z R V T]
time 20237ms: Process B completed I/O; added to ready queue [Q C F G P M W D K L O I Q Y A H S U Z R V T B]
time 20544ms: Process N completed a CPU burst; 49 bursts to go [Q C F G P M W D K L O I Q Y A H S U Z R V T B]
time 20544ms: Process N switching out of CPU; will block on I/O until time 20603ms [Q C F G P M W D K L O I Q Y A H S U Z R V T B]
time 20550ms: Process C started using the CPU for 217ms burst [Q F G P M W D K L O I Q Y A H S U Z R V T B]
time 20603ms: Process N completed I/O; added to ready queue [Q F G P M W D K L O I Q Y A H S U Z R V T B N]
time 20767ms: Process C completed a CPU burst; 49 bursts to go [Q F G P M W D K L O I Q Y A H S U Z R V T B N]
time 20767ms: Process C switching out of CPU; will block on I/O until time 20815ms [Q F G P M W D K L O I Q Y A H S U Z R V T B N]
time 20773ms: Process F started using the CPU for 48ms burst [Q G P M W D K L O I Q Y A H S U Z R V T B N]
time 20815ms: Process C completed I/O; added to ready queue [Q G P M W D K L O I Q Y A H S U Z R V T B N C]
time 20821ms: Process F completed a CPU burst; 5 bursts to go [Q G P M W D K L O I Q Y A H S U Z R V T B N C]
time 20821ms: Process F switching out of CPU; will block on I/O until time 20872ms [Q G P M W D K L O I Q Y A H S U Z R V T B N C]
time 20827ms: Process G started using the CPU for 142ms burst [Q P M W D K L O I Q Y A H S U Z R V T B N C]
time 20872ms: Process F completed I/O; added to ready queue [Q P M W D K L O I Q Y A H S U Z R V T B N C F]
time 20969ms: Process G completed a CPU burst; 70 bursts to go [Q P M W D K L O I Q Y A H S U Z R V T B N C F]
time 20969ms: Process G switching out of CPU; will block on I/O until time 21022ms [Q P M W D K L O I Q Y A H S U Z R V T B N C F]
time 20975ms: Process P started using the CPU for 76ms burst [Q M W D K L O I Q Y A H S U Z R V T B N C F]
time 21022ms: Process G completed I/O; added to ready queue [Q M W D K L O I Q Y A H S U Z R V T B N C F G]
time 21051ms: Process P completed a CPU burst; 76 bursts to go [Q M W D K L O I Q Y A H S U Z R V T B N C F G]
time 21051ms: Process P switching out of CPU; will block on I/O until time 21242ms [Q M W D K L O I Q Y A H S U Z R V T B N C F G]
time 21057ms: Process M started using the CPU for 11ms burst [Q W D K L O I Q Y A H S U Z R V T B N C F G]
time 21068ms: Process M completed a CPU burst; 29 bursts to go [Q W D K L O I Q Y A H S U Z R V T B N C F G]
time 21068ms: Process M switching out of CPU; will block on I/O until time 21125ms [Q W D K L O I Q Y A H S U Z R V T B N C F G]
time 21074ms: Process W started using the CPU for 228ms burst [Q D K L O I Q Y A H S U Z R V T B N C F G]
time 21125ms: Process M completed I/O; added to ready queue [Q D K L O I Q Y A H S U Z R V T B N C F G M]
time 21242ms: Process P completed I/O; added to ready queue [Q D K L O I Q Y A H S U Z R V T B N C F G M P]
time 21302ms: Process W completed a CPU burst; 14 bursts to go [Q D K L O I Q Y A H S U Z R V T B N C F G M P]
time 21302ms: Process W switching out of CPU; will block on I/O until time 21495ms [Q D K L O I Q Y A H S U Z R V T B N C F G M P]
time 21308ms: Process D started using the CPU for 65ms burst [Q K L O I Q Y A H S U Z R V T B N C F G M P]
time 21373ms: Process D completed a CPU burst; 59 bursts to go [Q K L O I Q Y A H S U Z R V T B N C F G M P]
time 21373ms: Process D switching out of CPU; will block on I/O until time 21393ms [Q K L O I Q Y A H S U Z R V T B N C F G M P]
time 21379ms: Process K started using the CPU for 32ms burst [Q L O I Q Y A H S U Z R V T B N C F G M P]
time 21393ms: Process D completed I/O; added to ready queue [Q L O I Q Y A H S U Z R V T B N C F G M P D]
time 21411ms: Process K completed a CPU burst; 79 bursts to go [Q L O I Q Y A H S U Z R V T B N C F G M P D]
time 21411ms: Process K switching out of CPU; will block on I/O until time 21521ms [Q L O I Q Y A H S U Z R V T B N C F G M P D]
time 21417ms: Process L started using the CPU for 91ms burst [Q O I Q Y A H S U Z R V T B N C F G M P D]
time 21495ms: Process W completed I/O; added to ready queue [Q O I Q Y A H S U Z R V T B N C F G M P D W]
time 21508ms: Process L completed a CPU burst; 16 bursts to go [Q O I Q Y A H S U Z R V T B N C F G M P D W]
time 21508ms: Process L switching out of CPU; will block on I/O until time 21597ms [Q O I Q Y A H S U Z R V T B N C F G M P D W]
time 21514ms: Process O started using the CPU for 49ms burst [Q I Q Y A H S U Z R V T B N C F G M P D W]
time 21521ms: Process K completed I/O; added to ready queue [Q I Q Y A H S U Z R V T B N C F G M P D W K]
time 21563ms: Process O completed a CPU burst; 47 bursts to go [Q I Q Y A H S U Z R V T B N C F G M P D W K]
time 21563ms: Process O switching out of CPU; will block on I/O until time 21627ms [Q I Q Y A H S U Z R V T B N C F G M P D W K]
time 21569ms: Process I started using the CPU for 133ms burst [Q Q Y A H S U Z R V T B N C F G M P D W K]
time 21597ms: Process L completed I/O; added to ready queue [Q Q Y A H S U Z R V T B N C F G M P D W K L]
time 21627ms: Process O completed I/O; added to ready queue [Q Q Y A H S U Z R V T B N C F G M P D W K L O]
time 21702ms: Process I completed a CPU burst; 50 bursts to go [Q Q Y A H S U Z R V T B N C F G M P D W K L O]
time 21702ms: Process I switching out of CPU; will block on I/O until time 21754ms [Q Q Y A H S U Z R V T B N C F G M P D W K L O]
time 21708ms: Process Q started using the CPU for 29ms burst [Q Y A H S U Z R V T B N C F G M P D W K L O]
time 21737ms: Process Q completed a CPU burst; 82 bursts to go [Q Y A H S U Z R V T B N C F G M P D W K L O]
time 21737ms: Process Q switching out of CPU; will block on I/O until time 21741ms [Q Y A H S U Z R V T B N C F G M P D W K L O]
time 21741ms: Process Q completed I/O; added to ready queue [Q A H S U Z R V T B N C F G M P D W K L O Q]
time 21743ms: Process Y started using the CPU for 35ms burst [Q A H S U Z R V T B N C F G M P D W K L O Q]
time 21754ms: Process I completed I/O; added to ready queue [Q A H S U Z R V T B N C F G M P D W K L O Q I]
time 21778ms: Process Y completed a CPU burst; 21 bursts to go [Q A H S U Z R V T B N C F G M P D W K L O Q I]
time 21778ms: Process Y switching out of CPU; will block on I/O until time 21789ms [Q A H S U Z R V T B N C F G M P D W K L O Q I]
time 21784ms: Process A started using the CPU for 34ms burst [Q H S U Z R V T B N C F G M P D W K L O Q I]
time 21789ms: Process Y completed I/O; added to ready queue [Q H S U Z R V T B N C F G M P D W K L O Q I Y]
time 21818ms: Process A completed a CPU burst; 66 bursts to go [Q H S U Z R V T B N C F G M P D W K L O Q I Y]
time 21818ms: Process A switching out of CPU; will block on I/O until time 22070ms [Q H S U Z R V T B N C F G M P D W K L O Q I Y]
time 21824ms: Process H started using the CPU for 207ms burst [Q S U Z R V T B N C F G M P D W K L O Q I Y]
time 22031ms: Process H completed a CPU burst; 45 bursts to go [Q S U Z R V T B N C F G M P D W K L O Q I Y]
time 22031ms: Process H switching out of CPU; will block on I/O until time 22315ms [Q S U Z R V T B N C F G M P D W K L O Q I Y]
time 22037ms: Process S started using the CPU for 169ms burst [Q U Z R V T B N C F G M P D W K L O Q I Y]
time 22070ms: Process A completed I/O; added to ready queue [Q U Z R V T B N C F G M P D W K L O Q I Y A]
time 22206ms: Process S completed a CPU burst; 23 bursts to go [Q U Z R V T B N C F G M P D W K L O Q I Y A]
time 22206ms: Process S switching out of CPU; will block on I/O until time 22236ms [Q U Z R V T B N C F G M P D W K L O Q I Y A]
time 22212ms: Process U started using the CPU for 19ms burst [Q Z R V T B N C F G M P D W K L O Q I Y A]
time 22231ms: Process U completed a CPU burst; 43 bursts to go [Q Z R V T B N C F G M P D W K L O Q I Y A]
time 22231ms: Process U switching out of CPU; will block on I/O until time 22379ms [Q Z R V T B N C F G M P D W K L O Q I Y A]
time 22236ms: Process S completed I/O; added to ready queue [Q R V T B N C F G M P D W K L O Q I Y A S]
time 22237ms: Process Z started using the CPU for 148ms burst [Q R V T B N C F G M P D W K L O Q I Y A S]
time 22315ms: Process H completed I/O; added to ready queue [Q R V T B N C F G M P D W K L O Q I Y A S H]
time 22379ms: Process U completed I/O; added to ready queue [Q R V T B N C F G M P D W K L O Q I Y A S H U]
time 22385ms: Process Z completed a CPU burst; 75 bursts to go [Q R V T B N C F G M P D W K L O Q I Y A S H U]
time 22385ms: Process Z switching out of CPU; will block on I/O until time 22446ms [Q R V T B N C F G M P D W K L O Q I Y A S H U]
time 22391ms: Process R started using the CPU for 48ms burst [Q V T B N C F G M P D W K L O Q I Y A S H U]
time 22439ms: Process R completed a CPU burst; 40 bursts to go [Q V T B N C F G M P D W K L O Q I Y A S H U]
time 22439ms: Process R switching out of CPU; will block on I/O until time 22460ms [Q V T B N C F G M P D W K L O Q I Y A S H U]
